Workbook

Sheet Hoja1
A1: POSICION C1 | C1: POSICION C2 | F1: TOAY
A2: 1 | B2: 25 | C2: 1 | D2: =+SUM(B2*0.75) -> 18.75 | F2: FECHA 1 | G2: Agus | H2: Pts | I2: Ema | J2: Pts | K2: JuanF | L2: Pts | M2: Adri | N2: Pts | O2: Adri | P2: Pts | Q2: Adri | R2: Pts | S2: Adri | T2: Pts | U2: Adri | V2: Pts | W2: Adri | X2: Pts | Y2: Adri | Z2: Pts | AA2: Adri | AB2: Pts | AC2: Adri | AD2: Pts
A3: 2 | B3: 18 | C3: 2 | D3: =+SUM(B3*0.75) -> 13.5 | F3: C1 | G3: 3 | H3: =+IF(G3=1,$B$2,IF($G3=2,$B$3,IF($G3=3,$B$4,IF($G3=4,$B$5,"")))) -> 15 | I3: 1 | J3: =+IF(I3=1,$B$2,IF($I3=2,$B$3,IF($I3=3,$B$4,IF($I3=4,$B$5,"")))) -> 25 | K3: 2 | L3: =+IF(K3=1,$B$2,IF($K3=2,$B$3,IF($K3=3,$B$4,IF($K3=4,$B$5,"")))) -> 18 | M3: 4 | N3: =+IF(M3=1,$B$2,IF($M3=2,$B$3,IF($M3=3,$B$4,IF($M3=4,$B$5,"")))) -> 12 | O3: 4 | P3: =+IF(O3=1,$B$2,IF($M3=2,$B$3,IF($M3=3,$B$4,IF($M3=4,$B$5,"")))) -> 12 | Q3: 4 | R3: =+IF(Q3=1,$B$2,IF($M3=2,$B$3,IF($M3=3,$B$4,IF($M3=4,$B$5,"")))) -> 12 | S3: 4 | T3: =+IF(S3=1,$B$2,IF($M3=2,$B$3,IF($M3=3,$B$4,IF($M3=4,$B$5,"")))) -> 12 | U3: 4 | V3: =+IF(U3=1,$B$2,IF($M3=2,$B$3,IF($M3=3,$B$4,IF($M3=4,$B$5,"")))) -> 12 | W3: 4 | X3: =+IF(W3=1,$B$2,IF($M3=2,$B$3,IF($M3=3,$B$4,IF($M3=4,$B$5,"")))) -> 12 | Y3: 4 | Z3: =+IF(Y3=1,$B$2,IF($M3=2,$B$3,IF($M3=3,$B$4,IF($M3=4,$B$5,"")))) -> 12 | AA3: 4 | AB3: =+IF(AA3=1,$B$2,IF($M3=2,$B$3,IF($M3=3,$B$4,IF($M3=4,$B$5,"")))) -> 12 | AC3: 4 | AD3: =+IF(AC3=1,$B$2,IF($M3=2,$B$3,IF($M3=3,$B$4,IF($M3=4,$B$5,"")))) -> 12
A4: 3 | B4: 15 | C4: 3 | D4: =+SUM(B4*0.75) -> 11.25 | F4: C2
A5: 4 | B5: 12 | C5: 4 | D5: =+SUM(B5*0.75) -> 9 | F5: Pole | N5: 1 | P5: 1 | R5: 1 | T5: 1 | V5: 1 | X5: 1 | Z5: 1 | AB5: 1 | AD5: 1
F6: VR1
B7: =+SUM(B2-B3) -> 7 | D7: =+SUM(D2-D3) -> 5.25 | F7: VR2
D8: =+SUM(D3-D4) -> 2.25 | F8: TOTAL FECHA | G8: =+SUM(H3:H7) -> 15 | I8: =+SUM(J3:J7) -> 25 | K8: =+SUM(L3:L7) -> 18 | M8: =+SUM(N3:N7) -> 13 | O8: =+SUM(P3:P7) -> 13 | Q8: =+SUM(R3:R7) -> 13 | S8: =+SUM(T3:T7) -> 13 | U8: =+SUM(V3:V7) -> 13 | W8: =+SUM(X3:X7) -> 13 | Y8: =+SUM(Z3:Z7) -> 13 | AA8: =+SUM(AB3:AB7) -> 13 | AC8: =+SUM(AD3:AD7) -> 13
D9: =+SUM(D4-D5) -> 2.25
F10: TOTAL | G10: =G8 -> 15 | I10: =I8 -> 25 | K10: =K8 -> 18 | M10: =M8 -> 13 | O10: =O8 -> 13 | Q10: =Q8 -> 13 | S10: =S8 -> 13 | U10: =U8 -> 13 | W10: =W8 -> 13 | Y10: =Y8 -> 13 | AA10: =AA8 -> 13 | AC10: =AC8 -> 13
F11: Lastre Fecha | G11: =+IF($G3=1,40,IF($G3=2,20,IF($G3=3,10,IF($G3=4,0,"")))) -> 10 | I11: =+IF($I3=1,40,IF($I3=2,20,IF($I3=3,10,IF($I3=4,0,"")))) -> 40 | K11: =+IF($K3=1,40,IF($K3=2,20,IF($K3=3,10,IF($K3=4,0,"")))) -> 20 | M11: =+IF($M3=1,40,IF($M3=2,20,IF($M3=3,10,IF($M3=4,0,"")))) -> 0 | O11: =+IF($M3=1,40,IF($M3=2,20,IF($M3=3,10,IF($M3=4,0,"")))) -> 0 | Q11: =+IF($M3=1,40,IF($M3=2,20,IF($M3=3,10,IF($M3=4,0,"")))) -> 0 | S11: =+IF($M3=1,40,IF($M3=2,20,IF($M3=3,10,IF($M3=4,0,"")))) -> 0 | U11: =+IF($M3=1,40,IF($M3=2,20,IF($M3=3,10,IF($M3=4,0,"")))) -> 0 | W11: =+IF($M3=1,40,IF($M3=2,20,IF($M3=3,10,IF($M3=4,0,"")))) -> 0 | Y11: =+IF($M3=1,40,IF($M3=2,20,IF($M3=3,10,IF($M3=4,0,"")))) -> 0 | AA11: =+IF($M3=1,40,IF($M3=2,20,IF($M3=3,10,IF($M3=4,0,"")))) -> 0 | AC11: =+IF($M3=1,40,IF($M3=2,20,IF($M3=3,10,IF($M3=4,0,"")))) -> 0
F12: Lastre Acumulado | G12: =+IF($G3=1,40,IF($G3=2,20,IF($G3=3,10,IF($G3=4,0,"")))) -> 10 | I12: =+IF($I3=1,40,IF($I3=2,20,IF($I3=3,10,IF($I3=4,0,"")))) -> 40 | K12: =+IF($K3=1,40,IF($K3=2,20,IF($K3=3,10,IF($K3=4,0,"")))) -> 20 | M12: =+IF($M3=1,40,IF($M3=2,20,IF($M3=3,10,IF($M3=4,0,"")))) -> 0 | O12: =+IF($M3=1,40,IF($M3=2,20,IF($M3=3,10,IF($M3=4,0,"")))) -> 0 | Q12: =+IF($M3=1,40,IF($M3=2,20,IF($M3=3,10,IF($M3=4,0,"")))) -> 0 | S12: =+IF($M3=1,40,IF($M3=2,20,IF($M3=3,10,IF($M3=4,0,"")))) -> 0 | U12: =+IF($M3=1,40,IF($M3=2,20,IF($M3=3,10,IF($M3=4,0,"")))) -> 0 | W12: =+IF($M3=1,40,IF($M3=2,20,IF($M3=3,10,IF($M3=4,0,"")))) -> 0 | Y12: =+IF($M3=1,40,IF($M3=2,20,IF($M3=3,10,IF($M3=4,0,"")))) -> 0 | AA12: =+IF($M3=1,40,IF($M3=2,20,IF($M3=3,10,IF($M3=4,0,"")))) -> 0 | AC12: =+IF($M3=1,40,IF($M3=2,20,IF($M3=3,10,IF($M3=4,0,"")))) -> 0
F15: FECHA 2
F16: C1
F17: C2
F18: Pole
F19: VR1
F20: VR2
F23: TOTAL
F24: Lastre Fecha
F25: Lastre Acumulado
F28: FECHA 3
F29: C1
F30: C2
... F38: Lastre Acumulado

Sheet Tabla Final
A1: PILOTO | B1: PTS | C1: KG | I1: PILOTO | J1: PTS | K1: KG | M1: Prom. Llegada | N1: Efectividad | O1: POLES
A2: Agus | B2: =+SUM(Hoja1!$G8,Hoja1!$G21,Hoja1!$G34,Hoja1!$G47,Hoja1!$G60,Hoja1!G73,Hoja1!G86,Hoja1!G99,Hoja1!G112) -> 15 | C2: =INDEX(Hoja1!$G$1:$G$250, (COUNTIF(DATOS!$J$4:$S$4, ">0")-1)*13 + 12) -> 10 | D2: =_xlfn.RANK.EQ(B2, $B$2:$B$5) + COUNTIF($B$2:B2, B2) - 1 -> 3 | E2: =+AVERAGEIF(DATOS!C$3:C$22, ">0") -> 3 | H2: 1 | I2: =INDEX($A$2:$A$5, MATCH(H2, $D$2:$D$5, 0)) -> Ema | J2: =INDEX($B$2:$B$5, MATCH(H2, $D$2:$D$5, 0)) -> 25 | K2: =INDEX($C$2:$C$5, MATCH(H2, $D$2:$D$5, 0)) -> 40 | M2: =INDEX($E$2:$E$5, MATCH(I2, $A$2:$A$5, 0)) -> 1 | N2: =J2 / (COUNTIFS(DATOS!D3:D22, ">0",DATOS!$B$3:$B$22, "CARRERA 1") * 46.75) -> 0.53475936 | O2: =SUM(DATOS!D27:D46) -> 0
A3: Ema | B3: =+SUM(Hoja1!$I8,Hoja1!$I21,Hoja1!$I34,Hoja1!$I47,Hoja1!$I60,Hoja1!I73,Hoja1!I86,Hoja1!I99,Hoja1!I112) -> 25 | C3: =INDEX(Hoja1!$I$1:$I$250, (COUNTIF(DATOS!$J$5:$S$5, ">0")-1)*13 + 12) -> 40 | D3: =_xlfn.RANK.EQ(B3, $B$2:$B$5) + COUNTIF($B$2:B3, B3) - 1 -> 1 | E3: =+AVERAGEIF(DATOS!D$3:D$22, ">0") -> 1 | H3: 2 | I3: =INDEX($A$2:$A$5, MATCH(H3, $D$2:$D$5, 0)) -> JuanF | J3: =INDEX($B$2:$B$5, MATCH(H3, $D$2:$D$5, 0)) -> 18 | K3: =INDEX($C$2:$C$5, MATCH(H3, $D$2:$D$5, 0)) -> 20 | M3: =INDEX($E$2:$E$5, MATCH(I3, $A$2:$A$5, 0)) -> 2 | N3: =J3 / (COUNTIFS(DATOS!D3:D22, ">0",DATOS!$B$3:$B$22, "CARRERA 1") * 46.75) -> 0.38502674 | O3: =+SUM(DATOS!C27:C46) -> 0
A4: JuanF | B4: =+SUM(Hoja1!K8,Hoja1!K21,Hoja1!K34,Hoja1!K47,Hoja1!K60,Hoja1!K73,Hoja1!K86,Hoja1!K99,,Hoja1!K112) -> 18 | C4: =INDEX(Hoja1!$K$1:$K$250, (COUNTIF(DATOS!$J$6:$S$6, ">0")-1)*13 + 12) -> 20 | D4: =_xlfn.RANK.EQ(B4, $B$2:$B$5) + COUNTIF($B$2:B4, B4) - 1 -> 2 | E4: =+AVERAGEIF(DATOS!E$3:E$22, ">0") -> 2 | H4: 3 | I4: =INDEX($A$2:$A$5, MATCH(H4, $D$2:$D$5, 0)) -> Agus | J4: =INDEX($B$2:$B$5, MATCH(H4, $D$2:$D$5, 0)) -> 15 | K4: =INDEX($C$2:$C$5, MATCH(H4, $D$2:$D$5, 0)) -> 10 | M4: =INDEX($E$2:$E$5, MATCH(I4, $A$2:$A$5, 0)) -> 3 | N4: =J4 / (COUNTIFS(DATOS!E3:E22, ">0",DATOS!$B$3:$B$22, "CARRERA 1") * 46.75) -> 0.32085561 | O4: =+SUM(DATOS!E27:E46) -> 0
A5: Adri | B5: =+SUM(Hoja1!M8,Hoja1!M21,Hoja1!M34,Hoja1!M47,Hoja1!M60,Hoja1!M73,Hoja1!M86,Hoja1!M99,,Hoja1!M112) -> 13 | C5: =INDEX(Hoja1!$M$1:$M$250, (COUNTIF(DATOS!$J$7:$S$7, ">0")-1)*13 + 12) -> 0 | D5: =_xlfn.RANK.EQ(B5, $B$2:$B$5) + COUNTIF($B$2:B5, B5) - 1 -> 4 | E5: =+AVERAGEIF(DATOS!F$3:F$22, ">0") -> 4 | H5: 4 | I5: =INDEX($A$2:$A$5, MATCH(H5, $D$2:$D$5, 0)) -> Adri | J5: =INDEX($B$2:$B$5, MATCH(H5, $D$2:$D$5, 0)) -> 13 | K5: =INDEX($C$2:$C$5, MATCH(H5, $D$2:$D$5, 0)) -> 0 | M5: =INDEX($E$2:$E$5, MATCH(I5, $A$2:$A$5, 0)) -> 4 | N5: =J5 / (COUNTIFS(DATOS!F3:F22, ">0",DATOS!$B$3:$B$22, "CARRERA 1") * 46.75) -> 0.27807487 | O5: =+SUM(DATOS!F27:F46) -> 1
A6: Agus | B6: =+SUM(Hoja1!$G12,Hoja1!$G25,Hoja1!$G38,Hoja1!$G51,Hoja1!$G64,Hoja1!G77,Hoja1!G90,Hoja1!G103,Hoja1!G116) -> 10 | C6: =INDEX(Hoja1!$G$1:$G$250, (COUNTIF(DATOS!$J$4:$S$4, ">0")-1)*13 + 12) -> 10 | H6: 5 | I6: =INDEX($A$2:$A$5, MATCH(H6, $D$2:$D$5, 0)) -> #N/A | J6: =INDEX($B$2:$B$5, MATCH(H6, $D$2:$D$5, 0)) -> #N/A | K6: =INDEX($C$2:$C$5, MATCH(H6, $D$2:$D$5, 0)) -> #N/A
A7: Ema | B7: =+SUM(Hoja1!$I12,Hoja1!$I25,Hoja1!$I38,Hoja1!$I51,Hoja1!$I64,Hoja1!I77,Hoja1!I90,Hoja1!I103,Hoja1!I116) -> 40 | C7: =INDEX(Hoja1!$I$1:$I$250, (COUNTIF(DATOS!$J$5:$S$5, ">0")-1)*13 + 12) -> 40 | H7: 6 | I7: =INDEX($A$2:$A$5, MATCH(H7, $D$2:$D$5, 0)) -> #N/A | J7: =INDEX($B$2:$B$5, MATCH(H7, $D$2:$D$5, 0)) -> #N/A | K7: =INDEX($C$2:$C$5, MATCH(H7, $D$2:$D$5, 0)) -> #N/A | N7: *Sobre puntos posibles
A8: JuanF | B8: =+SUM(Hoja1!K12,Hoja1!K25,Hoja1!K38,Hoja1!K51,Hoja1!K64,Hoja1!K77,Hoja1!K90,Hoja1!K103,,Hoja1!K116) -> 20 | C8: =INDEX(Hoja1!$K$1:$K$250, (COUNTIF(DATOS!$J$6:$S$6, ">0")-1)*13 + 12) -> 20 | H8: 7 | I8: =INDEX($A$2:$A$5, MATCH(H8, $D$2:$D$5, 0)) -> #N/A | J8: =INDEX($B$2:$B$5, MATCH(H8, $D$2:$D$5, 0)) -> #N/A | K8: =INDEX($C$2:$C$5, MATCH(H8, $D$2:$D$5, 0)) -> #N/A
A9: Adri | B9: =+SUM(Hoja1!M12,Hoja1!M25,Hoja1!M38,Hoja1!M51,Hoja1!M64,Hoja1!M77,Hoja1!M90,Hoja1!M103,,Hoja1!M116) -> 0 | C9: =INDEX(Hoja1!$M$1:$M$250, (COUNTIF(DATOS!$J$7:$S$7, ">0")-1)*13 + 12) -> 0 | H9: 8 | I9: =INDEX($A$2:$A$5, MATCH(H9, $D$2:$D$5, 0)) -> #N/A | J9: =INDEX($B$2:$B$5, MATCH(H9, $D$2:$D$5, 0)) -> #N/A | K9: =INDEX($C$2:$C$5, MATCH(H9, $D$2:$D$5, 0)) -> #N/A
A10: Agus | B10: =+SUM(Hoja1!$G16,Hoja1!$G29,Hoja1!$G42,Hoja1!$G55,Hoja1!$G68,Hoja1!G81,Hoja1!G94,Hoja1!G107,Hoja1!G120) -> 0 | C10: =INDEX(Hoja1!$G$1:$G$250, (COUNTIF(DATOS!$J$4:$S$4, ">0")-1)*13 + 12) -> 10 | H10: 9 | I10: =INDEX($A$2:$A$5, MATCH(H10, $D$2:$D$5, 0)) -> #N/A | J10: =INDEX($B$2:$B$5, MATCH(H10, $D$2:$D$5, 0)) -> #N/A | K10: =INDEX($C$2:$C$5, MATCH(H10, $D$2:$D$5, 0)) -> #N/A
A11: Ema | B11: =+SUM(Hoja1!$I16,Hoja1!$I29,Hoja1!$I42,Hoja1!$I55,Hoja1!$I68,Hoja1!I81,Hoja1!I94,Hoja1!I107,Hoja1!I120) -> 0 | C11: =INDEX(Hoja1!$I$1:$I$250, (COUNTIF(DATOS!$J$5:$S$5, ">0")-1)*13 + 12) -> 40 | H11: 10 | I11: =INDEX($A$2:$A$5, MATCH(H11, $D$2:$D$5, 0)) -> #N/A | J11: =INDEX($B$2:$B$5, MATCH(H11, $D$2:$D$5, 0)) -> #N/A | K11: =INDEX($C$2:$C$5, MATCH(H11, $D$2:$D$5, 0)) -> #N/A
A12: JuanF | B12: =+SUM(Hoja1!K16,Hoja1!K29,Hoja1!K42,Hoja1!K55,Hoja1!K68,Hoja1!K81,Hoja1!K94,Hoja1!K107,,Hoja1!K120) -> 0 | C12: =INDEX(Hoja1!$K$1:$K$250, (COUNTIF(DATOS!$J$6:$S$6, ">0")-1)*13 + 12) -> 20 | H12: 11 | I12: =INDEX($A$2:$A$5, MATCH(H12, $D$2:$D$5, 0)) -> #N/A | J12: =INDEX($B$2:$B$5, MATCH(H12, $D$2:$D$5, 0)) -> #N/A | K12: =INDEX($C$2:$C$5, MATCH(H12, $D$2:$D$5, 0)) -> #N/A
H13: 12 | I13: =INDEX($A$2:$A$5, MATCH(H13, $D$2:$D$5, 0)) -> #N/A | J13: =INDEX($B$2:$B$5, MATCH(H13, $D$2:$D$5, 0)) -> #N/A | K13: =INDEX($C$2:$C$5, MATCH(H13, $D$2:$D$5, 0)) -> #N/A
H14: 13 | I14: =INDEX($A$2:$A$5, MATCH(H14, $D$2:$D$5, 0)) -> #N/A | J14: =INDEX($B$2:$B$5, MATCH(H14, $D$2:$D$5, 0)) -> #N/A | K14: =INDEX($C$2:$C$5, MATCH(H14, $D$2:$D$5, 0)) -> #N/A
H15: 14 | I15: =INDEX($A$2:$A$5, MATCH(H15, $D$2:$D$5, 0)) -> #N/A | J15: =INDEX($B$2:$B$5, MATCH(H15, $D$2:$D$5, 0)) -> #N/A | K15: =INDEX($C$2:$C$5, MATCH(H15, $D$2:$D$5, 0)) -> #N/A

Sheet DATOS
I1: GRAFICO
A2: FECHA | C2: Agus | D2: Ema | E2: JuanF | F2: Adri
A3: Laguna Seca | B3: CARRERA 1 | C3: =Hoja1!G3 -> 3 | D3: =Hoja1!$I3 -> 1 | E3: =Hoja1!K3 -> 2 | F3: =Hoja1!M3 -> 4 | J3: F1 | K3: F2 | L3: F3 | M3: F4 | N3: F5 | O3: F6 | P3: F7 | Q3: F8 | R3: F9 | S3: F10
B4: CARRERA 2 | C4: =Hoja1!G4 -> 0 | D4: =Hoja1!$I4 -> 0 | E4: =Hoja1!K4 -> 0 | F4: =Hoja1!M4 -> 0 | I4: AGUS | J4: =IF(INDEX(Hoja1!$G$1:$G$250, (COLUMN(A1)-1)*13 + 10)=0, NA(), INDEX(Hoja1!$G$1:$G$250, (COLUMN(A1)-1)*13 + 10)) -> 15 | K4: =IF(INDEX(Hoja1!$G$1:$G$250, (COLUMN(B1)-1)*13 + 10)=0, NA(), INDEX(Hoja1!$G$1:$G$250, (COLUMN(B1)-1)*13 + 10)) -> #N/A | L4: =IF(INDEX(Hoja1!$G$1:$G$250, (COLUMN(C1)-1)*13 + 10)=0, NA(), INDEX(Hoja1!$G$1:$G$250, (COLUMN(C1)-1)*13 + 10)) -> #N/A | M4: =IF(INDEX(Hoja1!$G$1:$G$250, (COLUMN(D1)-1)*13 + 10)=0, NA(), INDEX(Hoja1!$G$1:$G$250, (COLUMN(D1)-1)*13 + 10)) -> #N/A | N4: =IF(INDEX(Hoja1!$G$1:$G$250, (COLUMN(E1)-1)*13 + 10)=0, NA(), INDEX(Hoja1!$G$1:$G$250, (COLUMN(E1)-1)*13 + 10)) -> #N/A | O4: =IF(INDEX(Hoja1!$G$1:$G$250, (COLUMN(F1)-1)*13 + 10)=0, NA(), INDEX(Hoja1!$G$1:$G$250, (COLUMN(F1)-1)*13 + 10)) -> #N/A | P4: =IF(INDEX(Hoja1!$G$1:$G$250, (COLUMN(G1)-1)*13 + 10)=0, NA(), INDEX(Hoja1!$G$1:$G$250, (COLUMN(G1)-1)*13 + 10)) -> #N/A | Q4: =IF(INDEX(Hoja1!$G$1:$G$250, (COLUMN(H1)-1)*13 + 10)=0, NA(), INDEX(Hoja1!$G$1:$G$250, (COLUMN(H1)-1)*13 + 10)) -> #N/A | ... S4: =IF(INDEX(Hoja1!$G$1:$G$250, (COLUMN(J1)-1)*13 + 10)=0, NA(), INDEX(Hoja1!$G$1:$G$250, (COLUMN(J1)-1)*13 + 10)) -> #N/A
B5: CARRERA 1 | C5: =Hoja1!G16 -> 0 | D5: =Hoja1!I16 -> 0 | E5: =Hoja1!K16 -> 0 | F5: =Hoja1!M16 -> 0 | I5: PABLO | J5: =IF(INDEX(Hoja1!$I$1:$I$250, (COLUMN(A1)-1)*13 + 10)=0, NA(), INDEX(Hoja1!$I$1:$I$250, (COLUMN(A1)-1)*13 + 10)) -> 25 | K5: =IF(INDEX(Hoja1!$I$1:$I$250, (COLUMN(B1)-1)*13 + 10)=0, NA(), INDEX(Hoja1!$I$1:$I$250, (COLUMN(B1)-1)*13 + 10)) -> #N/A | L5: =IF(INDEX(Hoja1!$I$1:$I$250, (COLUMN(C1)-1)*13 + 10)=0, NA(), INDEX(Hoja1!$I$1:$I$250, (COLUMN(C1)-1)*13 + 10)) -> #N/A | M5: =IF(INDEX(Hoja1!$I$1:$I$250, (COLUMN(D1)-1)*13 + 10)=0, NA(), INDEX(Hoja1!$I$1:$I$250, (COLUMN(D1)-1)*13 + 10)) -> #N/A | N5: =IF(INDEX(Hoja1!$I$1:$I$250, (COLUMN(E1)-1)*13 + 10)=0, NA(), INDEX(Hoja1!$I$1:$I$250, (COLUMN(E1)-1)*13 + 10)) -> #N/A | O5: =IF(INDEX(Hoja1!$I$1:$I$250, (COLUMN(F1)-1)*13 + 10)=0, NA(), INDEX(Hoja1!$I$1:$I$250, (COLUMN(F1)-1)*13 + 10)) -> #N/A | P5: =IF(INDEX(Hoja1!$I$1:$I$250, (COLUMN(G1)-1)*13 + 10)=0, NA(), INDEX(Hoja1!$I$1:$I$250, (COLUMN(G1)-1)*13 + 10)) -> #N/A | Q5: =IF(INDEX(Hoja1!$I$1:$I$250, (COLUMN(H1)-1)*13 + 10)=0, NA(), INDEX(Hoja1!$I$1:$I$250, (COLUMN(H1)-1)*13 + 10)) -> #N/A | ... S5: =IF(INDEX(Hoja1!$I$1:$I$250, (COLUMN(J1)-1)*13 + 10)=0, NA(), INDEX(Hoja1!$I$1:$I$250, (COLUMN(J1)-1)*13 + 10)) -> #N/A
B6: CARRERA 2 | C6: =Hoja1!G17 -> 0 | D6: =Hoja1!I17 -> 0 | E6: =Hoja1!K17 -> 0 | F6: =Hoja1!M17 -> 0 | I6: JUANDI | J6: =IF(INDEX(Hoja1!$K$1:$K$250, (COLUMN(A1)-1)*13 + 10)=0, NA(), INDEX(Hoja1!$K$1:$K$250, (COLUMN(A1)-1)*13 + 10)) -> 18 | K6: =IF(INDEX(Hoja1!$K$1:$K$250, (COLUMN(B1)-1)*13 + 10)=0, NA(), INDEX(Hoja1!$K$1:$K$250, (COLUMN(B1)-1)*13 + 10)) -> #N/A | L6: =IF(INDEX(Hoja1!$K$1:$K$250, (COLUMN(C1)-1)*13 + 10)=0, NA(), INDEX(Hoja1!$K$1:$K$250, (COLUMN(C1)-1)*13 + 10)) -> #N/A | M6: =IF(INDEX(Hoja1!$K$1:$K$250, (COLUMN(D1)-1)*13 + 10)=0, NA(), INDEX(Hoja1!$K$1:$K$250, (COLUMN(D1)-1)*13 + 10)) -> #N/A | N6: =IF(INDEX(Hoja1!$K$1:$K$250, (COLUMN(E1)-1)*13 + 10)=0, NA(), INDEX(Hoja1!$K$1:$K$250, (COLUMN(E1)-1)*13 + 10)) -> #N/A | O6: =IF(INDEX(Hoja1!$K$1:$K$250, (COLUMN(F1)-1)*13 + 10)=0, NA(), INDEX(Hoja1!$K$1:$K$250, (COLUMN(F1)-1)*13 + 10)) -> #N/A | P6: =IF(INDEX(Hoja1!$K$1:$K$250, (COLUMN(G1)-1)*13 + 10)=0, NA(), INDEX(Hoja1!$K$1:$K$250, (COLUMN(G1)-1)*13 + 10)) -> #N/A | Q6: =IF(INDEX(Hoja1!$K$1:$K$250, (COLUMN(H1)-1)*13 + 10)=0, NA(), INDEX(Hoja1!$K$1:$K$250, (COLUMN(H1)-1)*13 + 10)) -> #N/A | ... S6: =IF(INDEX(Hoja1!$K$1:$K$250, (COLUMN(J1)-1)*13 + 10)=0, NA(), INDEX(Hoja1!$K$1:$K$250, (COLUMN(J1)-1)*13 + 10)) -> #N/A
B7: CARRERA 1 | C7: =Hoja1!G29 -> 0 | D7: =Hoja1!I29 -> 0 | E7: =Hoja1!K29 -> 0 | F7: =Hoja1!M29 -> 0 | I7: EZE | J7: =IF(INDEX(Hoja1!$M$1:$M$250, (COLUMN(A1)-1)*13 + 10)=0, NA(), INDEX(Hoja1!$M$1:$M$250, (COLUMN(A1)-1)*13 + 10)) -> 13 | K7: =IF(INDEX(Hoja1!$M$1:$M$250, (COLUMN(B1)-1)*13 + 10)=0, NA(), INDEX(Hoja1!$M$1:$M$250, (COLUMN(B1)-1)*13 + 10)) -> #N/A | L7: =IF(INDEX(Hoja1!$M$1:$M$250, (COLUMN(C1)-1)*13 + 10)=0, NA(), INDEX(Hoja1!$M$1:$M$250, (COLUMN(C1)-1)*13 + 10)) -> #N/A | M7: =IF(INDEX(Hoja1!$M$1:$M$250, (COLUMN(D1)-1)*13 + 10)=0, NA(), INDEX(Hoja1!$M$1:$M$250, (COLUMN(D1)-1)*13 + 10)) -> #N/A | N7: =IF(INDEX(Hoja1!$M$1:$M$250, (COLUMN(E1)-1)*13 + 10)=0, NA(), INDEX(Hoja1!$M$1:$M$250, (COLUMN(E1)-1)*13 + 10)) -> #N/A | O7: =IF(INDEX(Hoja1!$M$1:$M$250, (COLUMN(F1)-1)*13 + 10)=0, NA(), INDEX(Hoja1!$M$1:$M$250, (COLUMN(F1)-1)*13 + 10)) -> #N/A | P7: =IF(INDEX(Hoja1!$M$1:$M$250, (COLUMN(G1)-1)*13 + 10)=0, NA(), INDEX(Hoja1!$M$1:$M$250, (COLUMN(G1)-1)*13 + 10)) -> #N/A | Q7: =IF(INDEX(Hoja1!$M$1:$M$250, (COLUMN(H1)-1)*13 + 10)=0, NA(), INDEX(Hoja1!$M$1:$M$250, (COLUMN(H1)-1)*13 + 10)) -> #N/A | ... S7: =IF(INDEX(Hoja1!$M$1:$M$250, (COLUMN(J1)-1)*13 + 10)=0, NA(), INDEX(Hoja1!$M$1:$M$250, (COLUMN(J1)-1)*13 + 10)) -> #N/A
B8: CARRERA 2 | C8: =Hoja1!G30 -> 0 | D8: =Hoja1!I30 -> 0 | E8: =Hoja1!K30 -> 0 | F8: =Hoja1!M30 -> 0
B9: CARRERA 1 | C9: =Hoja1!G42 -> 0 | D9: =Hoja1!I42 -> 0 | E9: =Hoja1!K42 -> 0 | F9: =Hoja1!M42 -> 0
B10: CARRERA 2 | C10: =Hoja1!G43 -> 0 | D10: =Hoja1!I43 -> 0 | E10: =Hoja1!K43 -> 0 | F10: =Hoja1!M43 -> 0
B11: CARRERA 1 | C11: =Hoja1!G55 -> 0 | D11: =Hoja1!I55 -> 0 | E11: =Hoja1!K55 -> 0 | F11: =Hoja1!M55 -> 0
B12: CARRERA 2 | C12: =Hoja1!G56 -> 0 | D12: =Hoja1!I56 -> 0 | E12: =Hoja1!K56 -> 0 | F12: =Hoja1!M56 -> 0
B13: CARRERA 1 | C13: =Hoja1!G68 -> 0 | D13: =Hoja1!I68 -> 0 | E13: =Hoja1!K68 -> 0 | F13: =Hoja1!M68 -> 0
B14: CARRERA 2 | C14: =Hoja1!G69 -> 0 | D14: =Hoja1!I69 -> 0 | E14: =Hoja1!K69 -> 0 | F14: =Hoja1!M69 -> 0
B15: CARRERA 1 | C15: =Hoja1!G81 -> 0 | D15: =Hoja1!I81 -> 0 | E15: =Hoja1!K81 -> 0 | F15: =Hoja1!M81 -> 0
B16: CARRERA 2 | C16: =Hoja1!G82 -> 0 | D16: =Hoja1!I82 -> 0 | E16: =Hoja1!K82 -> 0 | F16: =Hoja1!M82 -> 0
B17: CARRERA 1 | C17: =Hoja1!G94 -> 0 | D17: =Hoja1!I94 -> 0 | E17: =Hoja1!K94 -> 0 | F17: =Hoja1!M94 -> 0
B18: CARRERA 2 | C18: =Hoja1!G95 -> 0 | D18: =Hoja1!I95 -> 0 | E18: =Hoja1!K95 -> 0 | F18: =Hoja1!M95 -> 0
B19: CARRERA 1 | C19: =Hoja1!G107 -> 0 | D19: =Hoja1!I107 -> 0 | E19: =Hoja1!K107 -> 0 | F19: =Hoja1!M107 -> 0
B20: CARRERA 2 | C20: =Hoja1!G110 -> 0 | D20: =Hoja1!I110 -> 0 | E20: =Hoja1!K110 -> 0 | F20: =Hoja1!M110 -> 0
B21: CARRERA 1 | C21: =Hoja1!G122 -> 0 | D21: =Hoja1!I122 -> 0 | E21: =Hoja1!K122 -> 0 | F21: =Hoja1!M122 -> 0
B22: CARRERA 2 | C22: =Hoja1!G123 -> 0 | D22: =Hoja1!I123 -> 0 | E22: =Hoja1!K123 -> 0 | F22: =Hoja1!M123 -> 0
A24: Total victorias | C24: =+COUNTIF(C3:C22,1) -> 0 | D24: =+COUNTIF(D3:D22,1) -> 1 | E24: =+COUNTIF(E3:E22,1) -> 0 | F24: =+COUNTIF(F3:F22,1) -> 0
A25: POLES
A26: FECHA | C26: AGUS | D26: PABLO | E26: JUANDI | F26: EZE
A27: Laguna Seca | B27: POLE | C27: =Hoja1!H5 -> 0 | D27: =Hoja1!J5 -> 0 | E27: =Hoja1!L5 -> 0 | F27: =Hoja1!N5 -> 1
A47: TOTAL | C47: =+SUM(C27:C46) -> 0 | D47: =+SUM(D27:D46) -> 0 | E47: =+SUM(E27:E46) -> 0 | F47: =+SUM(F27:F46) -> 1

Sheet Comparativa
A1: FECHA | B1: PILOTO | C1: POLE | D1: VR | E1: VR2 | F1: POS C1 | G1: POS C2
A2: TOAY | C2: =INDEX(Hoja1!$A$1:$N$250, INT((ROW(A1)-1)/4)*13 + 5, CHOOSE(MOD(ROW(A1)-1,4)+1, 8, 10, 12, 14)) -> 0 | D2: =INDEX(Hoja1!$A$1:$N$250, INT((ROW(A1)-1)/4)*13 + 6, CHOOSE(MOD(ROW(A1)-1,4)+1, 8, 10, 12, 14)) -> 0 | E2: =INDEX(Hoja1!$A$1:$N$250, INT((ROW(A1)-1)/4)*13 + 7, CHOOSE(MOD(ROW(A1)-1,4)+1, 8, 10, 12, 14)) -> 0 | F2: =IF(INDEX(Hoja1!$A$1:$N$250, INT((ROW(A1)-1)/4)*13 + 3, CHOOSE(MOD(ROW(A1)-1,4)+1, 7, 9, 11, 13))=0, "", INDEX(Hoja1!$A$1:$N$250, INT((ROW(A1)-1)/4)*13 + 3, CHOOSE(MOD(ROW(A1)-1,4)+1, 7, 9, 11, 13))) -> 3 | G2: =IF(INDEX(Hoja1!$A$1:$N$250, INT((ROW(A1)-1)/4)*13 + 4, CHOOSE(MOD(ROW(A1)-1,4)+1, 7, 9, 11, 13))=0, "", INDEX(Hoja1!$A$1:$N$250, INT((ROW(A1)-1)/4)*13 + 4, CHOOSE(MOD(ROW(A1)-1,4)+1, 7, 9, 11, 13)))
A3: TOAY | C3: =INDEX(Hoja1!$A$1:$N$250, INT((ROW(A2)-1)/4)*13 + 5, CHOOSE(MOD(ROW(A2)-1,4)+1, 8, 10, 12, 14)) -> 0 | D3: =INDEX(Hoja1!$A$1:$N$250, INT((ROW(A2)-1)/4)*13 + 6, CHOOSE(MOD(ROW(A2)-1,4)+1, 8, 10, 12, 14)) -> 0 | E3: =INDEX(Hoja1!$A$1:$N$250, INT((ROW(A2)-1)/4)*13 + 7, CHOOSE(MOD(ROW(A2)-1,4)+1, 8, 10, 12, 14)) -> 0 | F3: =IF(INDEX(Hoja1!$A$1:$N$250, INT((ROW(A2)-1)/4)*13 + 3, CHOOSE(MOD(ROW(A2)-1,4)+1, 7, 9, 11, 13))=0, "", INDEX(Hoja1!$A$1:$N$250, INT((ROW(A2)-1)/4)*13 + 3, CHOOSE(MOD(ROW(A2)-1,4)+1, 7, 9, 11, 13))) -> 1 | G3: =IF(INDEX(Hoja1!$A$1:$N$250, INT((ROW(A2)-1)/4)*13 + 4, CHOOSE(MOD(ROW(A2)-1,4)+1, 7, 9, 11, 13))=0, "", INDEX(Hoja1!$A$1:$N$250, INT((ROW(A2)-1)/4)*13 + 4, CHOOSE(MOD(ROW(A2)-1,4)+1, 7, 9, 11, 13)))
A4: TOAY | C4: =INDEX(Hoja1!$A$1:$N$250, INT((ROW(A3)-1)/4)*13 + 5, CHOOSE(MOD(ROW(A3)-1,4)+1, 8, 10, 12, 14)) -> 0 | D4: =INDEX(Hoja1!$A$1:$N$250, INT((ROW(A3)-1)/4)*13 + 6, CHOOSE(MOD(ROW(A3)-1,4)+1, 8, 10, 12, 14)) -> 0 | E4: =INDEX(Hoja1!$A$1:$N$250, INT((ROW(A3)-1)/4)*13 + 7, CHOOSE(MOD(ROW(A3)-1,4)+1, 8, 10, 12, 14)) -> 0 | F4: =IF(INDEX(Hoja1!$A$1:$N$250, INT((ROW(A3)-1)/4)*13 + 3, CHOOSE(MOD(ROW(A3)-1,4)+1, 7, 9, 11, 13))=0, "", INDEX(Hoja1!$A$1:$N$250, INT((ROW(A3)-1)/4)*13 + 3, CHOOSE(MOD(ROW(A3)-1,4)+1, 7, 9, 11, 13))) -> 2 | G4: =IF(INDEX(Hoja1!$A$1:$N$250, INT((ROW(A3)-1)/4)*13 + 4, CHOOSE(MOD(ROW(A3)-1,4)+1, 7, 9, 11, 13))=0, "", INDEX(Hoja1!$A$1:$N$250, INT((ROW(A3)-1)/4)*13 + 4, CHOOSE(MOD(ROW(A3)-1,4)+1, 7, 9, 11, 13)))
A5: TOAY | C5: =INDEX(Hoja1!$A$1:$N$250, INT((ROW(A4)-1)/4)*13 + 5, CHOOSE(MOD(ROW(A4)-1,4)+1, 8, 10, 12, 14)) -> 1 | D5: =INDEX(Hoja1!$A$1:$N$250, INT((ROW(A4)-1)/4)*13 + 6, CHOOSE(MOD(ROW(A4)-1,4)+1, 8, 10, 12, 14)) -> 0 | E5: =INDEX(Hoja1!$A$1:$N$250, INT((ROW(A4)-1)/4)*13 + 7, CHOOSE(MOD(ROW(A4)-1,4)+1, 8, 10, 12, 14)) -> 0 | F5: =IF(INDEX(Hoja1!$A$1:$N$250, INT((ROW(A4)-1)/4)*13 + 3, CHOOSE(MOD(ROW(A4)-1,4)+1, 7, 9, 11, 13))=0, "", INDEX(Hoja1!$A$1:$N$250, INT((ROW(A4)-1)/4)*13 + 3, CHOOSE(MOD(ROW(A4)-1,4)+1, 7, 9, 11, 13))) -> 4 | G5: =IF(INDEX(Hoja1!$A$1:$N$250, INT((ROW(A4)-1)/4)*13 + 4, CHOOSE(MOD(ROW(A4)-1,4)+1, 7, 9, 11, 13))=0, "", INDEX(Hoja1!$A$1:$N$250, INT((ROW(A4)-1)/4)*13 + 4, CHOOSE(MOD(ROW(A4)-1,4)+1, 7, 9, 11, 13)))
C6: =INDEX(Hoja1!$A$1:$N$250, INT((ROW(A5)-1)/4)*13 + 5, CHOOSE(MOD(ROW(A5)-1,4)+1, 8, 10, 12, 14)) -> 0 | D6: =INDEX(Hoja1!$A$1:$N$250, INT((ROW(A5)-1)/4)*13 + 6, CHOOSE(MOD(ROW(A5)-1,4)+1, 8, 10, 12, 14)) -> 0 | E6: =INDEX(Hoja1!$A$1:$N$250, INT((ROW(A5)-1)/4)*13 + 7, CHOOSE(MOD(ROW(A5)-1,4)+1, 8, 10, 12, 14)) -> 0 | F6: =IF(INDEX(Hoja1!$A$1:$N$250, INT((ROW(A5)-1)/4)*13 + 3, CHOOSE(MOD(ROW(A5)-1,4)+1, 7, 9, 11, 13))=0, "", INDEX(Hoja1!$A$1:$N$250, INT((ROW(A5)-1)/4)*13 + 3, CHOOSE(MOD(ROW(A5)-1,4)+1, 7, 9, 11, 13))) | G6: =IF(INDEX(Hoja1!$A$1:$N$250, INT((ROW(A5)-1)/4)*13 + 4, CHOOSE(MOD(ROW(A5)-1,4)+1, 7, 9, 11, 13))=0, "", INDEX(Hoja1!$A$1:$N$250, INT((ROW(A5)-1)/4)*13 + 4, CHOOSE(MOD(ROW(A5)-1,4)+1, 7, 9, 11, 13)))
C7: =INDEX(Hoja1!$A$1:$N$250, INT((ROW(A6)-1)/4)*13 + 5, CHOOSE(MOD(ROW(A6)-1,4)+1, 8, 10, 12, 14)) -> 0 | D7: =INDEX(Hoja1!$A$1:$N$250, INT((ROW(A6)-1)/4)*13 + 6, CHOOSE(MOD(ROW(A6)-1,4)+1, 8, 10, 12, 14)) -> 0 | E7: =INDEX(Hoja1!$A$1:$N$250, INT((ROW(A6)-1)/4)*13 + 7, CHOOSE(MOD(ROW(A6)-1,4)+1, 8, 10, 12, 14)) -> 0 | F7: =IF(INDEX(Hoja1!$A$1:$N$250, INT((ROW(A6)-1)/4)*13 + 3, CHOOSE(MOD(ROW(A6)-1,4)+1, 7, 9, 11, 13))=0, "", INDEX(Hoja1!$A$1:$N$250, INT((ROW(A6)-1)/4)*13 + 3, CHOOSE(MOD(ROW(A6)-1,4)+1, 7, 9, 11, 13))) | G7: =IF(INDEX(Hoja1!$A$1:$N$250, INT((ROW(A6)-1)/4)*13 + 4, CHOOSE(MOD(ROW(A6)-1,4)+1, 7, 9, 11, 13))=0, "", INDEX(Hoja1!$A$1:$N$250, INT((ROW(A6)-1)/4)*13 + 4, CHOOSE(MOD(ROW(A6)-1,4)+1, 7, 9, 11, 13)))
C8: =INDEX(Hoja1!$A$1:$N$250, INT((ROW(A7)-1)/4)*13 + 5, CHOOSE(MOD(ROW(A7)-1,4)+1, 8, 10, 12, 14)) -> 0 | D8: =INDEX(Hoja1!$A$1:$N$250, INT((ROW(A7)-1)/4)*13 + 6, CHOOSE(MOD(ROW(A7)-1,4)+1, 8, 10, 12, 14)) -> 0 | E8: =INDEX(Hoja1!$A$1:$N$250, INT((ROW(A7)-1)/4)*13 + 7, CHOOSE(MOD(ROW(A7)-1,4)+1, 8, 10, 12, 14)) -> 0 | F8: =IF(INDEX(Hoja1!$A$1:$N$250, INT((ROW(A7)-1)/4)*13 + 3, CHOOSE(MOD(ROW(A7)-1,4)+1, 7, 9, 11, 13))=0, "", INDEX(Hoja1!$A$1:$N$250, INT((ROW(A7)-1)/4)*13 + 3, CHOOSE(MOD(ROW(A7)-1,4)+1, 7, 9, 11, 13))) | G8: =IF(INDEX(Hoja1!$A$1:$N$250, INT((ROW(A7)-1)/4)*13 + 4, CHOOSE(MOD(ROW(A7)-1,4)+1, 7, 9, 11, 13))=0, "", INDEX(Hoja1!$A$1:$N$250, INT((ROW(A7)-1)/4)*13 + 4, CHOOSE(MOD(ROW(A7)-1,4)+1, 7, 9, 11, 13)))
C9: =INDEX(Hoja1!$A$1:$N$250, INT((ROW(A8)-1)/4)*13 + 5, CHOOSE(MOD(ROW(A8)-1,4)+1, 8, 10, 12, 14)) -> 0 | D9: =INDEX(Hoja1!$A$1:$N$250, INT((ROW(A8)-1)/4)*13 + 6, CHOOSE(MOD(ROW(A8)-1,4)+1, 8, 10, 12, 14)) -> 0 | E9: =INDEX(Hoja1!$A$1:$N$250, INT((ROW(A8)-1)/4)*13 + 7, CHOOSE(MOD(ROW(A8)-1,4)+1, 8, 10, 12, 14)) -> 0 | F9: =IF(INDEX(Hoja1!$A$1:$N$250, INT((ROW(A8)-1)/4)*13 + 3, CHOOSE(MOD(ROW(A8)-1,4)+1, 7, 9, 11, 13))=0, "", INDEX(Hoja1!$A$1:$N$250, INT((ROW(A8)-1)/4)*13 + 3, CHOOSE(MOD(ROW(A8)-1,4)+1, 7, 9, 11, 13))) | G9: =IF(INDEX(Hoja1!$A$1:$N$250, INT((ROW(A8)-1)/4)*13 + 4, CHOOSE(MOD(ROW(A8)-1,4)+1, 7, 9, 11, 13))=0, "", INDEX(Hoja1!$A$1:$N$250, INT((ROW(A8)-1)/4)*13 + 4, CHOOSE(MOD(ROW(A8)-1,4)+1, 7, 9, 11, 13)))
C10: =INDEX(Hoja1!$A$1:$N$250, INT((ROW(A9)-1)/4)*13 + 5, CHOOSE(MOD(ROW(A9)-1,4)+1, 8, 10, 12, 14)) -> 0 | D10: =INDEX(Hoja1!$A$1:$N$250, INT((ROW(A9)-1)/4)*13 + 6, CHOOSE(MOD(ROW(A9)-1,4)+1, 8, 10, 12, 14)) -> 0 | E10: =INDEX(Hoja1!$A$1:$N$250, INT((ROW(A9)-1)/4)*13 + 7, CHOOSE(MOD(ROW(A9)-1,4)+1, 8, 10, 12, 14)) -> 0 | F10: =IF(INDEX(Hoja1!$A$1:$N$250, INT((ROW(A9)-1)/4)*13 + 3, CHOOSE(MOD(ROW(A9)-1,4)+1, 7, 9, 11, 13))=0, "", INDEX(Hoja1!$A$1:$N$250, INT((ROW(A9)-1)/4)*13 + 3, CHOOSE(MOD(ROW(A9)-1,4)+1, 7, 9, 11, 13))) | G10: =IF(INDEX(Hoja1!$A$1:$N$250, INT((ROW(A9)-1)/4)*13 + 4, CHOOSE(MOD(ROW(A9)-1,4)+1, 7, 9, 11, 13))=0, "", INDEX(Hoja1!$A$1:$N$250, INT((ROW(A9)-1)/4)*13 + 4, CHOOSE(MOD(ROW(A9)-1,4)+1, 7, 9, 11, 13)))
C11: =INDEX(Hoja1!$A$1:$N$250, INT((ROW(A10)-1)/4)*13 + 5, CHOOSE(MOD(ROW(A10)-1,4)+1, 8, 10, 12, 14)) -> 0 | D11: =INDEX(Hoja1!$A$1:$N$250, INT((ROW(A10)-1)/4)*13 + 6, CHOOSE(MOD(ROW(A10)-1,4)+1, 8, 10, 12, 14)) -> 0 | E11: =INDEX(Hoja1!$A$1:$N$250, INT((ROW(A10)-1)/4)*13 + 7, CHOOSE(MOD(ROW(A10)-1,4)+1, 8, 10, 12, 14)) -> 0 | F11: =IF(INDEX(Hoja1!$A$1:$N$250, INT((ROW(A10)-1)/4)*13 + 3, CHOOSE(MOD(ROW(A10)-1,4)+1, 7, 9, 11, 13))=0, "", INDEX(Hoja1!$A$1:$N$250, INT((ROW(A10)-1)/4)*13 + 3, CHOOSE(MOD(ROW(A10)-1,4)+1, 7, 9, 11, 13))) | G11: =IF(INDEX(Hoja1!$A$1:$N$250, INT((ROW(A10)-1)/4)*13 + 4, CHOOSE(MOD(ROW(A10)-1,4)+1, 7, 9, 11, 13))=0, "", INDEX(Hoja1!$A$1:$N$250, INT((ROW(A10)-1)/4)*13 + 4, CHOOSE(MOD(ROW(A10)-1,4)+1, 7, 9, 11, 13)))
C12: =INDEX(Hoja1!$A$1:$N$250, INT((ROW(A11)-1)/4)*13 + 5, CHOOSE(MOD(ROW(A11)-1,4)+1, 8, 10, 12, 14)) -> 0 | D12: =INDEX(Hoja1!$A$1:$N$250, INT((ROW(A11)-1)/4)*13 + 6, CHOOSE(MOD(ROW(A11)-1,4)+1, 8, 10, 12, 14)) -> 0 | E12: =INDEX(Hoja1!$A$1:$N$250, INT((ROW(A11)-1)/4)*13 + 7, CHOOSE(MOD(ROW(A11)-1,4)+1, 8, 10, 12, 14)) -> 0 | F12: =IF(INDEX(Hoja1!$A$1:$N$250, INT((ROW(A11)-1)/4)*13 + 3, CHOOSE(MOD(ROW(A11)-1,4)+1, 7, 9, 11, 13))=0, "", INDEX(Hoja1!$A$1:$N$250, INT((ROW(A11)-1)/4)*13 + 3, CHOOSE(MOD(ROW(A11)-1,4)+1, 7, 9, 11, 13))) | G12: =IF(INDEX(Hoja1!$A$1:$N$250, INT((ROW(A11)-1)/4)*13 + 4, CHOOSE(MOD(ROW(A11)-1,4)+1, 7, 9, 11, 13))=0, "", INDEX(Hoja1!$A$1:$N$250, INT((ROW(A11)-1)/4)*13 + 4, CHOOSE(MOD(ROW(A11)-1,4)+1, 7, 9, 11, 13)))
C13: =INDEX(Hoja1!$A$1:$N$250, INT((ROW(A12)-1)/4)*13 + 5, CHOOSE(MOD(ROW(A12)-1,4)+1, 8, 10, 12, 14)) -> 0 | D13: =INDEX(Hoja1!$A$1:$N$250, INT((ROW(A12)-1)/4)*13 + 6, CHOOSE(MOD(ROW(A12)-1,4)+1, 8, 10, 12, 14)) -> 0 | E13: =INDEX(Hoja1!$A$1:$N$250, INT((ROW(A12)-1)/4)*13 + 7, CHOOSE(MOD(ROW(A12)-1,4)+1, 8, 10, 12, 14)) -> 0 | F13: =IF(INDEX(Hoja1!$A$1:$N$250, INT((ROW(A12)-1)/4)*13 + 3, CHOOSE(MOD(ROW(A12)-1,4)+1, 7, 9, 11, 13))=0, "", INDEX(Hoja1!$A$1:$N$250, INT((ROW(A12)-1)/4)*13 + 3, CHOOSE(MOD(ROW(A12)-1,4)+1, 7, 9, 11, 13))) | G13: =IF(INDEX(Hoja1!$A$1:$N$250, INT((ROW(A12)-1)/4)*13 + 4, CHOOSE(MOD(ROW(A12)-1,4)+1, 7, 9, 11, 13))=0, "", INDEX(Hoja1!$A$1:$N$250, INT((ROW(A12)-1)/4)*13 + 4, CHOOSE(MOD(ROW(A12)-1,4)+1, 7, 9, 11, 13)))
C14: =INDEX(Hoja1!$A$1:$N$250, INT((ROW(A13)-1)/4)*13 + 5, CHOOSE(MOD(ROW(A13)-1,4)+1, 8, 10, 12, 14)) -> 0 | D14: =INDEX(Hoja1!$A$1:$N$250, INT((ROW(A13)-1)/4)*13 + 6, CHOOSE(MOD(ROW(A13)-1,4)+1, 8, 10, 12, 14)) -> 0 | E14: =INDEX(Hoja1!$A$1:$N$250, INT((ROW(A13)-1)/4)*13 + 7, CHOOSE(MOD(ROW(A13)-1,4)+1, 8, 10, 12, 14)) -> 0 | F14: =IF(INDEX(Hoja1!$A$1:$N$250, INT((ROW(A13)-1)/4)*13 + 3, CHOOSE(MOD(ROW(A13)-1,4)+1, 7, 9, 11, 13))=0, "", INDEX(Hoja1!$A$1:$N$250, INT((ROW(A13)-1)/4)*13 + 3, CHOOSE(MOD(ROW(A13)-1,4)+1, 7, 9, 11, 13))) | G14: =IF(INDEX(Hoja1!$A$1:$N$250, INT((ROW(A13)-1)/4)*13 + 4, CHOOSE(MOD(ROW(A13)-1,4)+1, 7, 9, 11, 13))=0, "", INDEX(Hoja1!$A$1:$N$250, INT((ROW(A13)-1)/4)*13 + 4, CHOOSE(MOD(ROW(A13)-1,4)+1, 7, 9, 11, 13)))
C15: =INDEX(Hoja1!$A$1:$N$250, INT((ROW(A14)-1)/4)*13 + 5, CHOOSE(MOD(ROW(A14)-1,4)+1, 8, 10, 12, 14)) -> 0 | D15: =INDEX(Hoja1!$A$1:$N$250, INT((ROW(A14)-1)/4)*13 + 6, CHOOSE(MOD(ROW(A14)-1,4)+1, 8, 10, 12, 14)) -> 0 | E15: =INDEX(Hoja1!$A$1:$N$250, INT((ROW(A14)-1)/4)*13 + 7, CHOOSE(MOD(ROW(A14)-1,4)+1, 8, 10, 12, 14)) -> 0 | F15: =IF(INDEX(Hoja1!$A$1:$N$250, INT((ROW(A14)-1)/4)*13 + 3, CHOOSE(MOD(ROW(A14)-1,4)+1, 7, 9, 11, 13))=0, "", INDEX(Hoja1!$A$1:$N$250, INT((ROW(A14)-1)/4)*13 + 3, CHOOSE(MOD(ROW(A14)-1,4)+1, 7, 9, 11, 13))) | G15: =IF(INDEX(Hoja1!$A$1:$N$250, INT((ROW(A14)-1)/4)*13 + 4, CHOOSE(MOD(ROW(A14)-1,4)+1, 7, 9, 11, 13))=0, "", INDEX(Hoja1!$A$1:$N$250, INT((ROW(A14)-1)/4)*13 + 4, CHOOSE(MOD(ROW(A14)-1,4)+1, 7, 9, 11, 13)))
C16: =INDEX(Hoja1!$A$1:$N$250, INT((ROW(A15)-1)/4)*13 + 5, CHOOSE(MOD(ROW(A15)-1,4)+1, 8, 10, 12, 14)) -> 0 | D16: =INDEX(Hoja1!$A$1:$N$250, INT((ROW(A15)-1)/4)*13 + 6, CHOOSE(MOD(ROW(A15)-1,4)+1, 8, 10, 12, 14)) -> 0 | E16: =INDEX(Hoja1!$A$1:$N$250, INT((ROW(A15)-1)/4)*13 + 7, CHOOSE(MOD(ROW(A15)-1,4)+1, 8, 10, 12, 14)) -> 0 | F16: =IF(INDEX(Hoja1!$A$1:$N$250, INT((ROW(A15)-1)/4)*13 + 3, CHOOSE(MOD(ROW(A15)-1,4)+1, 7, 9, 11, 13))=0, "", INDEX(Hoja1!$A$1:$N$250, INT((ROW(A15)-1)/4)*13 + 3, CHOOSE(MOD(ROW(A15)-1,4)+1, 7, 9, 11, 13))) | G16: =IF(INDEX(Hoja1!$A$1:$N$250, INT((ROW(A15)-1)/4)*13 + 4, CHOOSE(MOD(ROW(A15)-1,4)+1, 7, 9, 11, 13))=0, "", INDEX(Hoja1!$A$1:$N$250, INT((ROW(A15)-1)/4)*13 + 4, CHOOSE(MOD(ROW(A15)-1,4)+1, 7, 9, 11, 13)))
C17: =INDEX(Hoja1!$A$1:$N$250, INT((ROW(A16)-1)/4)*13 + 5, CHOOSE(MOD(ROW(A16)-1,4)+1, 8, 10, 12, 14)) -> 0 | D17: =INDEX(Hoja1!$A$1:$N$250, INT((ROW(A16)-1)/4)*13 + 6, CHOOSE(MOD(ROW(A16)-1,4)+1, 8, 10, 12, 14)) -> 0 | E17: =INDEX(Hoja1!$A$1:$N$250, INT((ROW(A16)-1)/4)*13 + 7, CHOOSE(MOD(ROW(A16)-1,4)+1, 8, 10, 12, 14)) -> 0 | F17: =IF(INDEX(Hoja1!$A$1:$N$250, INT((ROW(A16)-1)/4)*13 + 3, CHOOSE(MOD(ROW(A16)-1,4)+1, 7, 9, 11, 13))=0, "", INDEX(Hoja1!$A$1:$N$250, INT((ROW(A16)-1)/4)*13 + 3, CHOOSE(MOD(ROW(A16)-1,4)+1, 7, 9, 11, 13))) | G17: =IF(INDEX(Hoja1!$A$1:$N$250, INT((ROW(A16)-1)/4)*13 + 4, CHOOSE(MOD(ROW(A16)-1,4)+1, 7, 9, 11, 13))=0, "", INDEX(Hoja1!$A$1:$N$250, INT((ROW(A16)-1)/4)*13 + 4, CHOOSE(MOD(ROW(A16)-1,4)+1, 7, 9, 11, 13)))
... C41: =INDEX(Hoja1!$A$1:$N$250, INT((ROW(A40)-1)/4)*13 + 5, CHOOSE(MOD(ROW(A40)-1,4)+1, 8, 10, 12, 14)) -> 0 | D41: =INDEX(Hoja1!$A$1:$N$250, INT((ROW(A40)-1)/4)*13 + 6, CHOOSE(MOD(ROW(A40)-1,4)+1, 8, 10, 12, 14)) -> 0 | E41: =INDEX(Hoja1!$A$1:$N$250, INT((ROW(A40)-1)/4)*13 + 7, CHOOSE(MOD(ROW(A40)-1,4)+1, 8, 10, 12, 14)) -> 0 | F41: =IF(INDEX(Hoja1!$A$1:$N$250, INT((ROW(A40)-1)/4)*13 + 3, CHOOSE(MOD(ROW(A40)-1,4)+1, 7, 9, 11, 13))=0, "", INDEX(Hoja1!$A$1:$N$250, INT((ROW(A40)-1)/4)*13 + 3, CHOOSE(MOD(ROW(A40)-1,4)+1, 7, 9, 11, 13))) | G41: =IF(INDEX(Hoja1!$A$1:$N$250, INT((ROW(A40)-1)/4)*13 + 4, CHOOSE(MOD(ROW(A40)-1,4)+1, 7, 9, 11, 13))=0, "", INDEX(Hoja1!$A$1:$N$250, INT((ROW(A40)-1)/4)*13 + 4, CHOOSE(MOD(ROW(A40)-1,4)+1, 7, 9, 11, 13)))

Sheet Carga Tiempos
C1: Agus | D1: Ema | E1: JuanF | F1: Adri
A2: TOAY | B2: Clasificacion | C2: 0.0010411343 | D2: 0.0010390046 | E2: 0.0010461458 | F2: 0.0010222454
B3: VR Carrera 1 | C3: 0.0010291782 | D3: 0.0010282639 | E3: 0.0010374074 | F3: 0.0010204282
B4: VR Carrera 2
B5: Clasificacion
B6: VR Carrera 1
B7: VR Carrera 2
B8: Clasificacion
B9: VR Carrera 1
B10: VR Carrera 2
B11: Clasificacion
B12: VR Carrera 1
B13: VR Carrera 2 | P13: =4/9*100 -> 44.444444
B14: Clasificacion | H14: {=IFERROR(AVERAGE(IF(($B$2:$B$46="Clasificacion")*(C$2:C$46>0),C$2:C$46)),0)} -> 0.0010411343 | I14: {=IFERROR(AVERAGE(IF(($B$2:$B$46="Clasificacion")*(D$2:D$46>0),D$2:D$46)),0)} -> 0.0010390046 | J14: {=IFERROR(AVERAGE(IF(($B$2:$B$46="Clasificacion")*(E$2:E$46>0),E$2:E$46)),0)} -> 0.0010461458 | K14: {=IFERROR(AVERAGE(IF(($B$2:$B$46="Clasificacion")*(F$2:F$46>0),F$2:F$46)),0)} -> 0.0010222454 | P14: =2/9*100 -> 22.222222
B15: VR Carrera 1 | H15: {=IFERROR(AVERAGE(IF(($B$2:$B$46="VR Carrera 1")*(C$2:C$46>0),C$2:C$46)),0)} -> 0.0010291782 | I15: {=IFERROR(AVERAGE(IF(($B$2:$B$46="VR Carrera 1")*(D$2:D$46>0),D$2:D$46)),0)} -> 0.0010282639 | J15: =IFERROR(AVERAGEIFS(E$2:E$46, $B$2:$B$46, "VR Carrera 1", E$2:E$46, ">0"), 0) -> 0.0010374074 | K15: {=IFERROR(AVERAGE(IF(($B$2:$B$46="VR Carrera 1")*(F$2:F$46>0),F$2:F$46)),0)} -> 0.0010204282
B16: VR Carrera 2 | H16: {=IFERROR(AVERAGE(IF(($B$2:$B$46="VR Carrera 2")*(C$2:C$46>0),C$2:C$46)),0)} -> 0 | I16: {=IFERROR(AVERAGE(IF(($B$2:$B$46="VR Carrera 2")*(D$2:D$46>0),D$2:D$46)),0)} -> 0 | J16: =IFERROR(AVERAGE(IF(($B$2:$B$46="VR Carrera 2")*(E$2:E$46>0),E$2:E$46)),0) -> 0 | K16: {=IFERROR(AVERAGE(IF(($B$2:$B$46="VR Carrera 2")*(F$2:F$46>0),F$2:F$46)),0)} -> 0
B17: Clasificacion
B18: VR Carrera 1 | R18: =25*0.75 -> 18.75
B19: VR Carrera 2
B20: Clasificacion
B21: VR Carrera 1
B22: VR Carrera 2
B23: Clasificacion
B24: VR Carrera 1
B25: VR Carrera 2
B26: Clasificacion
B27: VR Carrera 1
B28: VR Carrera 2
B29: Clasificacion
B30: VR Carrera 1
... B34: VR Carrera 2

Sheet Tiempos
A2: TOAY | B2: Clasificacion | C2: =+IF('Carga Tiempos'!C2=MIN('Carga Tiempos'!$C2:$F2),'Carga Tiempos'!C2,'Carga Tiempos'!C2-MIN('Carga Tiempos'!$C2:$F2)) -> 1.8888889e-05 | D2: =+IF('Carga Tiempos'!D2=MIN('Carga Tiempos'!$C2:$F2),'Carga Tiempos'!D2,'Carga Tiempos'!D2-MIN('Carga Tiempos'!$C2:$F2)) -> 1.6759259e-05 | E2: =+IF('Carga Tiempos'!E2=MIN('Carga Tiempos'!$C2:$F2),'Carga Tiempos'!E2,'Carga Tiempos'!E2-MIN('Carga Tiempos'!$C2:$F2)) -> 2.3900463e-05 | F2: =+IF('Carga Tiempos'!F2=MIN('Carga Tiempos'!$C2:$F2),'Carga Tiempos'!F2,'Carga Tiempos'!F2-MIN('Carga Tiempos'!$C2:$F2)) -> 0.0010222454 | G2: =+IF('Carga Tiempos'!G2=MIN('Carga Tiempos'!$C2:$F2),'Carga Tiempos'!G2,'Carga Tiempos'!G2-MIN('Carga Tiempos'!$C2:$F2)) -> -0.0010222454 | H2: =+IF('Carga Tiempos'!H2=MIN('Carga Tiempos'!$C2:$F2),'Carga Tiempos'!H2,'Carga Tiempos'!H2-MIN('Carga Tiempos'!$C2:$F2)) -> -0.0010222454 | I2: =+IF('Carga Tiempos'!I2=MIN('Carga Tiempos'!$C2:$F2),'Carga Tiempos'!I2,'Carga Tiempos'!I2-MIN('Carga Tiempos'!$C2:$F2)) -> -0.0010222454 | J2: =+IF('Carga Tiempos'!J2=MIN('Carga Tiempos'!$C2:$F2),'Carga Tiempos'!J2,'Carga Tiempos'!J2-MIN('Carga Tiempos'!$C2:$F2)) -> -0.0010222454 | ... M2: =+IF('Carga Tiempos'!M2=MIN('Carga Tiempos'!$C2:$F2),'Carga Tiempos'!M2,'Carga Tiempos'!M2-MIN('Carga Tiempos'!$C2:$F2)) -> -0.0010222454
B3: VR Carrera 1 | C3: =+IF('Carga Tiempos'!C3=MIN('Carga Tiempos'!$C3:$F3),'Carga Tiempos'!C3,'Carga Tiempos'!C3-MIN('Carga Tiempos'!$C3:$F3)) -> 8.75e-06 | D3: =+IF('Carga Tiempos'!D3=MIN('Carga Tiempos'!$C3:$F3),'Carga Tiempos'!D3,'Carga Tiempos'!D3-MIN('Carga Tiempos'!$C3:$F3)) -> 7.8356481e-06 | E3: =+IF('Carga Tiempos'!E3=MIN('Carga Tiempos'!$C3:$F3),'Carga Tiempos'!E3,'Carga Tiempos'!E3-MIN('Carga Tiempos'!$C3:$F3)) -> 1.6979167e-05 | F3: =+IF('Carga Tiempos'!F3=MIN('Carga Tiempos'!$C3:$F3),'Carga Tiempos'!F3,'Carga Tiempos'!F3-MIN('Carga Tiempos'!$C3:$F3)) -> 0.0010204282 | G3: =+IF('Carga Tiempos'!G3=MIN('Carga Tiempos'!$C3:$F3),'Carga Tiempos'!G3,'Carga Tiempos'!G3-MIN('Carga Tiempos'!$C3:$F3)) -> -0.0010204282 | H3: =+IF('Carga Tiempos'!H3=MIN('Carga Tiempos'!$C3:$F3),'Carga Tiempos'!H3,'Carga Tiempos'!H3-MIN('Carga Tiempos'!$C3:$F3)) -> -0.0010204282 | I3: =+IF('Carga Tiempos'!I3=MIN('Carga Tiempos'!$C3:$F3),'Carga Tiempos'!I3,'Carga Tiempos'!I3-MIN('Carga Tiempos'!$C3:$F3)) -> -0.0010204282 | J3: =+IF('Carga Tiempos'!J3=MIN('Carga Tiempos'!$C3:$F3),'Carga Tiempos'!J3,'Carga Tiempos'!J3-MIN('Carga Tiempos'!$C3:$F3)) -> -0.0010204282 | ... M3: =+IF('Carga Tiempos'!M3=MIN('Carga Tiempos'!$C3:$F3),'Carga Tiempos'!M3,'Carga Tiempos'!M3-MIN('Carga Tiempos'!$C3:$F3)) -> -0.0010204282
B4: VR Carrera 2 | C4: =+IF('Carga Tiempos'!C4=MIN('Carga Tiempos'!$C4:$F4),'Carga Tiempos'!C4,'Carga Tiempos'!C4-MIN('Carga Tiempos'!$C4:$F4)) -> 0 | D4: =+IF('Carga Tiempos'!D4=MIN('Carga Tiempos'!$C4:$F4),'Carga Tiempos'!D4,'Carga Tiempos'!D4-MIN('Carga Tiempos'!$C4:$F4)) -> 0 | E4: =+IF('Carga Tiempos'!E4=MIN('Carga Tiempos'!$C4:$F4),'Carga Tiempos'!E4,'Carga Tiempos'!E4-MIN('Carga Tiempos'!$C4:$F4)) -> 0 | F4: =+IF('Carga Tiempos'!F4=MIN('Carga Tiempos'!$C4:$F4),'Carga Tiempos'!F4,'Carga Tiempos'!F4-MIN('Carga Tiempos'!$C4:$F4)) -> 0 | G4: =+IF('Carga Tiempos'!G4=MIN('Carga Tiempos'!$C4:$F4),'Carga Tiempos'!G4,'Carga Tiempos'!G4-MIN('Carga Tiempos'!$C4:$F4)) -> 0 | H4: =+IF('Carga Tiempos'!H4=MIN('Carga Tiempos'!$C4:$F4),'Carga Tiempos'!H4,'Carga Tiempos'!H4-MIN('Carga Tiempos'!$C4:$F4)) -> 0 | I4: =+IF('Carga Tiempos'!I4=MIN('Carga Tiempos'!$C4:$F4),'Carga Tiempos'!I4,'Carga Tiempos'!I4-MIN('Carga Tiempos'!$C4:$F4)) -> 0 | J4: =+IF('Carga Tiempos'!J4=MIN('Carga Tiempos'!$C4:$F4),'Carga Tiempos'!J4,'Carga Tiempos'!J4-MIN('Carga Tiempos'!$C4:$F4)) -> 0 | ... M4: =+IF('Carga Tiempos'!M4=MIN('Carga Tiempos'!$C4:$F4),'Carga Tiempos'!M4,'Carga Tiempos'!M4-MIN('Carga Tiempos'!$C4:$F4)) -> 0
B5: Clasificacion
B6: VR Carrera 1
B7: VR Carrera 2
B8: Clasificacion
B9: VR Carrera 1 | P9: Columna1 | Q9: Agus | R9: Pablo | S9: Eze
B10: VR Carrera 2 | C10: =+IF('Carga Tiempos'!C10=MIN('Carga Tiempos'!$C10:$F10),'Carga Tiempos'!C10,'Carga Tiempos'!C10-MIN('Carga Tiempos'!$C10:$F10)) -> 0 | D10: =+IF('Carga Tiempos'!D10=MIN('Carga Tiempos'!$C10:$F10),'Carga Tiempos'!D10,'Carga Tiempos'!D10-MIN('Carga Tiempos'!$C10:$F10)) -> 0 | E10: =+IF('Carga Tiempos'!E10=MIN('Carga Tiempos'!$C10:$F10),'Carga Tiempos'!E10,'Carga Tiempos'!E10-MIN('Carga Tiempos'!$C10:$F10)) -> 0 | F10: =+IF('Carga Tiempos'!F10=MIN('Carga Tiempos'!$C10:$F10),'Carga Tiempos'!F10,'Carga Tiempos'!F10-MIN('Carga Tiempos'!$C10:$F10)) -> 0 | G10: =+IF('Carga Tiempos'!G10=MIN('Carga Tiempos'!$C10:$F10),'Carga Tiempos'!G10,'Carga Tiempos'!G10-MIN('Carga Tiempos'!$C10:$F10)) -> 0 | H10: =+IF('Carga Tiempos'!H10=MIN('Carga Tiempos'!$C10:$F10),'Carga Tiempos'!H10,'Carga Tiempos'!H10-MIN('Carga Tiempos'!$C10:$F10)) -> 0 | I10: =+IF('Carga Tiempos'!I10=MIN('Carga Tiempos'!$C10:$F10),'Carga Tiempos'!I10,'Carga Tiempos'!I10-MIN('Carga Tiempos'!$C10:$F10)) -> 0 | J10: =+IF('Carga Tiempos'!J10=MIN('Carga Tiempos'!$C10:$F10),'Carga Tiempos'!J10,'Carga Tiempos'!J10-MIN('Carga Tiempos'!$C10:$F10)) -> 0 | ... M10: =+IF('Carga Tiempos'!M10=MIN('Carga Tiempos'!$C10:$F10),'Carga Tiempos'!M10,'Carga Tiempos'!M10-MIN('Carga Tiempos'!$C10:$F10)) -> 0 | P10: POLES | Q10: =IF('Carga Tiempos'!H14=MIN('Carga Tiempos'!$H14,'Carga Tiempos'!$I14,'Carga Tiempos'!$K14),0,'Carga Tiempos'!H14-MIN('Carga Tiempos'!$H14,'Carga Tiempos'!$I14,'Carga Tiempos'!$K14)) -> 1.8888889e-05 | R10: =IF('Carga Tiempos'!I14=MIN('Carga Tiempos'!$H14,'Carga Tiempos'!$I14,'Carga Tiempos'!$K14),0,'Carga Tiempos'!I14-MIN('Carga Tiempos'!$H14,'Carga Tiempos'!$I14,'Carga Tiempos'!$K14)) -> 1.6759259e-05 | S10: =IF('Carga Tiempos'!K14=MIN('Carga Tiempos'!$H14,'Carga Tiempos'!$I14,'Carga Tiempos'!$K14),0,'Carga Tiempos'!K14-MIN('Carga Tiempos'!$H14,'Carga Tiempos'!$I14,'Carga Tiempos'!$K14)) -> 0
B11: Clasificacion | C11: =+IF('Carga Tiempos'!C11=MIN('Carga Tiempos'!$C11:$F11),'Carga Tiempos'!C11,'Carga Tiempos'!C11-MIN('Carga Tiempos'!$C11:$F11)) -> 0 | D11: =+IF('Carga Tiempos'!D11=MIN('Carga Tiempos'!$C11:$F11),'Carga Tiempos'!D11,'Carga Tiempos'!D11-MIN('Carga Tiempos'!$C11:$F11)) -> 0 | E11: =+IF('Carga Tiempos'!E11=MIN('Carga Tiempos'!$C11:$F11),'Carga Tiempos'!E11,'Carga Tiempos'!E11-MIN('Carga Tiempos'!$C11:$F11)) -> 0 | F11: =+IF('Carga Tiempos'!F11=MIN('Carga Tiempos'!$C11:$F11),'Carga Tiempos'!F11,'Carga Tiempos'!F11-MIN('Carga Tiempos'!$C11:$F11)) -> 0 | G11: =+IF('Carga Tiempos'!G11=MIN('Carga Tiempos'!$C11:$F11),'Carga Tiempos'!G11,'Carga Tiempos'!G11-MIN('Carga Tiempos'!$C11:$F11)) -> 0 | H11: =+IF('Carga Tiempos'!H11=MIN('Carga Tiempos'!$C11:$F11),'Carga Tiempos'!H11,'Carga Tiempos'!H11-MIN('Carga Tiempos'!$C11:$F11)) -> 0 | I11: =+IF('Carga Tiempos'!I11=MIN('Carga Tiempos'!$C11:$F11),'Carga Tiempos'!I11,'Carga Tiempos'!I11-MIN('Carga Tiempos'!$C11:$F11)) -> 0 | J11: =+IF('Carga Tiempos'!J11=MIN('Carga Tiempos'!$C11:$F11),'Carga Tiempos'!J11,'Carga Tiempos'!J11-MIN('Carga Tiempos'!$C11:$F11)) -> 0 | ... M11: =+IF('Carga Tiempos'!M11=MIN('Carga Tiempos'!$C11:$F11),'Carga Tiempos'!M11,'Carga Tiempos'!M11-MIN('Carga Tiempos'!$C11:$F11)) -> 0 | P11: CARRERA 1 | Q11: =IF('Carga Tiempos'!H15=MIN('Carga Tiempos'!$H15,'Carga Tiempos'!$I15,'Carga Tiempos'!$K15),0,'Carga Tiempos'!H15-MIN('Carga Tiempos'!$H15,'Carga Tiempos'!$I15,'Carga Tiempos'!$K15)) -> 8.75e-06 | R11: =IF('Carga Tiempos'!I15=MIN('Carga Tiempos'!$H15,'Carga Tiempos'!$I15,'Carga Tiempos'!$K15),0,'Carga Tiempos'!I15-MIN('Carga Tiempos'!$H15,'Carga Tiempos'!$I15,'Carga Tiempos'!$K15)) -> 7.8356481e-06 | S11: =IF('Carga Tiempos'!K15=MIN('Carga Tiempos'!$H15,'Carga Tiempos'!$I15,'Carga Tiempos'!$K15),0,'Carga Tiempos'!K15-MIN('Carga Tiempos'!$H15,'Carga Tiempos'!$I15,'Carga Tiempos'!$K15)) -> 0
B12: VR Carrera 1 | P12: CARRERA 2 | Q12: =IF('Carga Tiempos'!H16=MIN('Carga Tiempos'!$H16,'Carga Tiempos'!$I16,'Carga Tiempos'!$K16),0,'Carga Tiempos'!H16-MIN('Carga Tiempos'!$H16,'Carga Tiempos'!$I16,'Carga Tiempos'!$K16)) -> 0 | R12: =IF('Carga Tiempos'!I16=MIN('Carga Tiempos'!$H16,'Carga Tiempos'!$I16,'Carga Tiempos'!$K16),0,'Carga Tiempos'!I16-MIN('Carga Tiempos'!$H16,'Carga Tiempos'!$I16,'Carga Tiempos'!$K16)) -> 0 | S12: =IF('Carga Tiempos'!K16=MIN('Carga Tiempos'!$H16,'Carga Tiempos'!$I16,'Carga Tiempos'!$K16),0,'Carga Tiempos'!K16-MIN('Carga Tiempos'!$H16,'Carga Tiempos'!$I16,'Carga Tiempos'!$K16)) -> 0
B13: VR Carrera 2
B14: Clasificacion | C14: =+IF('Carga Tiempos'!C14=MIN('Carga Tiempos'!$C14:$F14),'Carga Tiempos'!C14,'Carga Tiempos'!C14-MIN('Carga Tiempos'!$C14:$F14)) -> 0 | D14: =+IF('Carga Tiempos'!D14=MIN('Carga Tiempos'!$C14:$F14),'Carga Tiempos'!D14,'Carga Tiempos'!D14-MIN('Carga Tiempos'!$C14:$F14)) -> 0 | E14: =+IF('Carga Tiempos'!E14=MIN('Carga Tiempos'!$C14:$F14),'Carga Tiempos'!E14,'Carga Tiempos'!E14-MIN('Carga Tiempos'!$C14:$F14)) -> 0 | F14: =+IF('Carga Tiempos'!F14=MIN('Carga Tiempos'!$C14:$F14),'Carga Tiempos'!F14,'Carga Tiempos'!F14-MIN('Carga Tiempos'!$C14:$F14)) -> 0 | G14: =+IF('Carga Tiempos'!G14=MIN('Carga Tiempos'!$C14:$F14),'Carga Tiempos'!G14,'Carga Tiempos'!G14-MIN('Carga Tiempos'!$C14:$F14)) -> 0 | H14: =+IF('Carga Tiempos'!H14=MIN('Carga Tiempos'!$C14:$F14),'Carga Tiempos'!H14,'Carga Tiempos'!H14-MIN('Carga Tiempos'!$C14:$F14)) -> 0.0010411343 | I14: =+IF('Carga Tiempos'!I14=MIN('Carga Tiempos'!$C14:$F14),'Carga Tiempos'!I14,'Carga Tiempos'!I14-MIN('Carga Tiempos'!$C14:$F14)) -> 0.0010390046 | J14: =+IF('Carga Tiempos'!J14=MIN('Carga Tiempos'!$C14:$F14),'Carga Tiempos'!J14,'Carga Tiempos'!J14-MIN('Carga Tiempos'!$C14:$F14)) -> 0.0010461458 | ... M14: =+IF('Carga Tiempos'!M14=MIN('Carga Tiempos'!$C14:$F14),'Carga Tiempos'!M14,'Carga Tiempos'!M14-MIN('Carga Tiempos'!$C14:$F14)) -> 0
B15: VR Carrera 1 | C15: =+IF('Carga Tiempos'!C15=MIN('Carga Tiempos'!$C15:$F15),'Carga Tiempos'!C15,'Carga Tiempos'!C15-MIN('Carga Tiempos'!$C15:$F15)) -> 0 | D15: =+IF('Carga Tiempos'!D15=MIN('Carga Tiempos'!$C15:$F15),'Carga Tiempos'!D15,'Carga Tiempos'!D15-MIN('Carga Tiempos'!$C15:$F15)) -> 0 | E15: =+IF('Carga Tiempos'!E15=MIN('Carga Tiempos'!$C15:$F15),'Carga Tiempos'!E15,'Carga Tiempos'!E15-MIN('Carga Tiempos'!$C15:$F15)) -> 0 | F15: =+IF('Carga Tiempos'!F15=MIN('Carga Tiempos'!$C15:$F15),'Carga Tiempos'!F15,'Carga Tiempos'!F15-MIN('Carga Tiempos'!$C15:$F15)) -> 0 | G15: =+IF('Carga Tiempos'!G15=MIN('Carga Tiempos'!$C15:$F15),'Carga Tiempos'!G15,'Carga Tiempos'!G15-MIN('Carga Tiempos'!$C15:$F15)) -> 0 | H15: =+IF('Carga Tiempos'!H15=MIN('Carga Tiempos'!$C15:$F15),'Carga Tiempos'!H15,'Carga Tiempos'!H15-MIN('Carga Tiempos'!$C15:$F15)) -> 0.0010291782 | I15: =+IF('Carga Tiempos'!I15=MIN('Carga Tiempos'!$C15:$F15),'Carga Tiempos'!I15,'Carga Tiempos'!I15-MIN('Carga Tiempos'!$C15:$F15)) -> 0.0010282639 | J15: =+IF('Carga Tiempos'!J15=MIN('Carga Tiempos'!$C15:$F15),'Carga Tiempos'!J15,'Carga Tiempos'!J15-MIN('Carga Tiempos'!$C15:$F15)) -> 0.0010374074 | ... M15: =+IF('Carga Tiempos'!M15=MIN('Carga Tiempos'!$C15:$F15),'Carga Tiempos'!M15,'Carga Tiempos'!M15-MIN('Carga Tiempos'!$C15:$F15)) -> 0
B16: VR Carrera 2 | C16: =+IF('Carga Tiempos'!C16=MIN('Carga Tiempos'!$C16:$F16),'Carga Tiempos'!C16,'Carga Tiempos'!C16-MIN('Carga Tiempos'!$C16:$F16)) -> 0 | D16: =+IF('Carga Tiempos'!D16=MIN('Carga Tiempos'!$C16:$F16),'Carga Tiempos'!D16,'Carga Tiempos'!D16-MIN('Carga Tiempos'!$C16:$F16)) -> 0 | E16: =+IF('Carga Tiempos'!E16=MIN('Carga Tiempos'!$C16:$F16),'Carga Tiempos'!E16,'Carga Tiempos'!E16-MIN('Carga Tiempos'!$C16:$F16)) -> 0 | F16: =+IF('Carga Tiempos'!F16=MIN('Carga Tiempos'!$C16:$F16),'Carga Tiempos'!F16,'Carga Tiempos'!F16-MIN('Carga Tiempos'!$C16:$F16)) -> 0 | G16: =+IF('Carga Tiempos'!G16=MIN('Carga Tiempos'!$C16:$F16),'Carga Tiempos'!G16,'Carga Tiempos'!G16-MIN('Carga Tiempos'!$C16:$F16)) -> 0 | H16: =+IF('Carga Tiempos'!H16=MIN('Carga Tiempos'!$C16:$F16),'Carga Tiempos'!H16,'Carga Tiempos'!H16-MIN('Carga Tiempos'!$C16:$F16)) -> 0 | I16: =+IF('Carga Tiempos'!I16=MIN('Carga Tiempos'!$C16:$F16),'Carga Tiempos'!I16,'Carga Tiempos'!I16-MIN('Carga Tiempos'!$C16:$F16)) -> 0 | J16: =+IF('Carga Tiempos'!J16=MIN('Carga Tiempos'!$C16:$F16),'Carga Tiempos'!J16,'Carga Tiempos'!J16-MIN('Carga Tiempos'!$C16:$F16)) -> 0 | ... M16: =+IF('Carga Tiempos'!M16=MIN('Carga Tiempos'!$C16:$F16),'Carga Tiempos'!M16,'Carga Tiempos'!M16-MIN('Carga Tiempos'!$C16:$F16)) -> 0
B17: Clasificacion | C17: =+IF('Carga Tiempos'!C17=MIN('Carga Tiempos'!$C17:$F17),'Carga Tiempos'!C17,'Carga Tiempos'!C17-MIN('Carga Tiempos'!$C17:$F17)) -> 0 | D17: =+IF('Carga Tiempos'!D17=MIN('Carga Tiempos'!$C17:$F17),'Carga Tiempos'!D17,'Carga Tiempos'!D17-MIN('Carga Tiempos'!$C17:$F17)) -> 0 | E17: =+IF('Carga Tiempos'!E17=MIN('Carga Tiempos'!$C17:$F17),'Carga Tiempos'!E17,'Carga Tiempos'!E17-MIN('Carga Tiempos'!$C17:$F17)) -> 0 | F17: =+IF('Carga Tiempos'!F17=MIN('Carga Tiempos'!$C17:$F17),'Carga Tiempos'!F17,'Carga Tiempos'!F17-MIN('Carga Tiempos'!$C17:$F17)) -> 0 | G17: =+IF('Carga Tiempos'!G17=MIN('Carga Tiempos'!$C17:$F17),'Carga Tiempos'!G17,'Carga Tiempos'!G17-MIN('Carga Tiempos'!$C17:$F17)) -> 0 | H17: =+IF('Carga Tiempos'!H17=MIN('Carga Tiempos'!$C17:$F17),'Carga Tiempos'!H17,'Carga Tiempos'!H17-MIN('Carga Tiempos'!$C17:$F17)) -> 0 | I17: =+IF('Carga Tiempos'!I17=MIN('Carga Tiempos'!$C17:$F17),'Carga Tiempos'!I17,'Carga Tiempos'!I17-MIN('Carga Tiempos'!$C17:$F17)) -> 0 | J17: =+IF('Carga Tiempos'!J17=MIN('Carga Tiempos'!$C17:$F17),'Carga Tiempos'!J17,'Carga Tiempos'!J17-MIN('Carga Tiempos'!$C17:$F17)) -> 0 | ... M17: =+IF('Carga Tiempos'!M17=MIN('Carga Tiempos'!$C17:$F17),'Carga Tiempos'!M17,'Carga Tiempos'!M17-MIN('Carga Tiempos'!$C17:$F17)) -> 0
B18: VR Carrera 1 | C18: =+IF('Carga Tiempos'!C18=MIN('Carga Tiempos'!$C18:$F18),'Carga Tiempos'!C18,'Carga Tiempos'!C18-MIN('Carga Tiempos'!$C18:$F18)) -> 0 | D18: =+IF('Carga Tiempos'!D18=MIN('Carga Tiempos'!$C18:$F18),'Carga Tiempos'!D18,'Carga Tiempos'!D18-MIN('Carga Tiempos'!$C18:$F18)) -> 0 | E18: =+IF('Carga Tiempos'!E18=MIN('Carga Tiempos'!$C18:$F18),'Carga Tiempos'!E18,'Carga Tiempos'!E18-MIN('Carga Tiempos'!$C18:$F18)) -> 0 | F18: =+IF('Carga Tiempos'!F18=MIN('Carga Tiempos'!$C18:$F18),'Carga Tiempos'!F18,'Carga Tiempos'!F18-MIN('Carga Tiempos'!$C18:$F18)) -> 0 | G18: =+IF('Carga Tiempos'!G18=MIN('Carga Tiempos'!$C18:$F18),'Carga Tiempos'!G18,'Carga Tiempos'!G18-MIN('Carga Tiempos'!$C18:$F18)) -> 0 | H18: =+IF('Carga Tiempos'!H18=MIN('Carga Tiempos'!$C18:$F18),'Carga Tiempos'!H18,'Carga Tiempos'!H18-MIN('Carga Tiempos'!$C18:$F18)) -> 0 | I18: =+IF('Carga Tiempos'!I18=MIN('Carga Tiempos'!$C18:$F18),'Carga Tiempos'!I18,'Carga Tiempos'!I18-MIN('Carga Tiempos'!$C18:$F18)) -> 0 | J18: =+IF('Carga Tiempos'!J18=MIN('Carga Tiempos'!$C18:$F18),'Carga Tiempos'!J18,'Carga Tiempos'!J18-MIN('Carga Tiempos'!$C18:$F18)) -> 0 | ... M18: =+IF('Carga Tiempos'!M18=MIN('Carga Tiempos'!$C18:$F18),'Carga Tiempos'!M18,'Carga Tiempos'!M18-MIN('Carga Tiempos'!$C18:$F18)) -> 0
B19: VR Carrera 2 | C19: =+IF('Carga Tiempos'!C19=MIN('Carga Tiempos'!$C19:$F19),'Carga Tiempos'!C19,'Carga Tiempos'!C19-MIN('Carga Tiempos'!$C19:$F19)) -> 0 | D19: =+IF('Carga Tiempos'!D19=MIN('Carga Tiempos'!$C19:$F19),'Carga Tiempos'!D19,'Carga Tiempos'!D19-MIN('Carga Tiempos'!$C19:$F19)) -> 0 | E19: =+IF('Carga Tiempos'!E19=MIN('Carga Tiempos'!$C19:$F19),'Carga Tiempos'!E19,'Carga Tiempos'!E19-MIN('Carga Tiempos'!$C19:$F19)) -> 0 | F19: =+IF('Carga Tiempos'!F19=MIN('Carga Tiempos'!$C19:$F19),'Carga Tiempos'!F19,'Carga Tiempos'!F19-MIN('Carga Tiempos'!$C19:$F19)) -> 0 | G19: =+IF('Carga Tiempos'!G19=MIN('Carga Tiempos'!$C19:$F19),'Carga Tiempos'!G19,'Carga Tiempos'!G19-MIN('Carga Tiempos'!$C19:$F19)) -> 0 | H19: =+IF('Carga Tiempos'!H19=MIN('Carga Tiempos'!$C19:$F19),'Carga Tiempos'!H19,'Carga Tiempos'!H19-MIN('Carga Tiempos'!$C19:$F19)) -> 0 | I19: =+IF('Carga Tiempos'!I19=MIN('Carga Tiempos'!$C19:$F19),'Carga Tiempos'!I19,'Carga Tiempos'!I19-MIN('Carga Tiempos'!$C19:$F19)) -> 0 | J19: =+IF('Carga Tiempos'!J19=MIN('Carga Tiempos'!$C19:$F19),'Carga Tiempos'!J19,'Carga Tiempos'!J19-MIN('Carga Tiempos'!$C19:$F19)) -> 0 | ... M19: =+IF('Carga Tiempos'!M19=MIN('Carga Tiempos'!$C19:$F19),'Carga Tiempos'!M19,'Carga Tiempos'!M19-MIN('Carga Tiempos'!$C19:$F19)) -> 0
B20: Clasificacion | C20: =+IF('Carga Tiempos'!C20=MIN('Carga Tiempos'!$C20:$F20),'Carga Tiempos'!C20,'Carga Tiempos'!C20-MIN('Carga Tiempos'!$C20:$F20)) -> 0 | D20: =+IF('Carga Tiempos'!D20=MIN('Carga Tiempos'!$C20:$F20),'Carga Tiempos'!D20,'Carga Tiempos'!D20-MIN('Carga Tiempos'!$C20:$F20)) -> 0 | E20: =+IF('Carga Tiempos'!E20=MIN('Carga Tiempos'!$C20:$F20),'Carga Tiempos'!E20,'Carga Tiempos'!E20-MIN('Carga Tiempos'!$C20:$F20)) -> 0 | F20: =+IF('Carga Tiempos'!F20=MIN('Carga Tiempos'!$C20:$F20),'Carga Tiempos'!F20,'Carga Tiempos'!F20-MIN('Carga Tiempos'!$C20:$F20)) -> 0 | G20: =+IF('Carga Tiempos'!G20=MIN('Carga Tiempos'!$C20:$F20),'Carga Tiempos'!G20,'Carga Tiempos'!G20-MIN('Carga Tiempos'!$C20:$F20)) -> 0 | H20: =+IF('Carga Tiempos'!H20=MIN('Carga Tiempos'!$C20:$F20),'Carga Tiempos'!H20,'Carga Tiempos'!H20-MIN('Carga Tiempos'!$C20:$F20)) -> 0 | I20: =+IF('Carga Tiempos'!I20=MIN('Carga Tiempos'!$C20:$F20),'Carga Tiempos'!I20,'Carga Tiempos'!I20-MIN('Carga Tiempos'!$C20:$F20)) -> 0 | J20: =+IF('Carga Tiempos'!J20=MIN('Carga Tiempos'!$C20:$F20),'Carga Tiempos'!J20,'Carga Tiempos'!J20-MIN('Carga Tiempos'!$C20:$F20)) -> 0 | ... M20: =+IF('Carga Tiempos'!M20=MIN('Carga Tiempos'!$C20:$F20),'Carga Tiempos'!M20,'Carga Tiempos'!M20-MIN('Carga Tiempos'!$C20:$F20)) -> 0
B21: VR Carrera 1 | C21: =+IF('Carga Tiempos'!C21=MIN('Carga Tiempos'!$C21:$F21),'Carga Tiempos'!C21,'Carga Tiempos'!C21-MIN('Carga Tiempos'!$C21:$F21)) -> 0 | D21: =+IF('Carga Tiempos'!D21=MIN('Carga Tiempos'!$C21:$F21),'Carga Tiempos'!D21,'Carga Tiempos'!D21-MIN('Carga Tiempos'!$C21:$F21)) -> 0 | E21: =+IF('Carga Tiempos'!E21=MIN('Carga Tiempos'!$C21:$F21),'Carga Tiempos'!E21,'Carga Tiempos'!E21-MIN('Carga Tiempos'!$C21:$F21)) -> 0 | F21: =+IF('Carga Tiempos'!F21=MIN('Carga Tiempos'!$C21:$F21),'Carga Tiempos'!F21,'Carga Tiempos'!F21-MIN('Carga Tiempos'!$C21:$F21)) -> 0 | G21: =+IF('Carga Tiempos'!G21=MIN('Carga Tiempos'!$C21:$F21),'Carga Tiempos'!G21,'Carga Tiempos'!G21-MIN('Carga Tiempos'!$C21:$F21)) -> 0 | H21: =+IF('Carga Tiempos'!H21=MIN('Carga Tiempos'!$C21:$F21),'Carga Tiempos'!H21,'Carga Tiempos'!H21-MIN('Carga Tiempos'!$C21:$F21)) -> 0 | I21: =+IF('Carga Tiempos'!I21=MIN('Carga Tiempos'!$C21:$F21),'Carga Tiempos'!I21,'Carga Tiempos'!I21-MIN('Carga Tiempos'!$C21:$F21)) -> 0 | J21: =+IF('Carga Tiempos'!J21=MIN('Carga Tiempos'!$C21:$F21),'Carga Tiempos'!J21,'Carga Tiempos'!J21-MIN('Carga Tiempos'!$C21:$F21)) -> 0 | ... M21: =+IF('Carga Tiempos'!M21=MIN('Carga Tiempos'!$C21:$F21),'Carga Tiempos'!M21,'Carga Tiempos'!M21-MIN('Carga Tiempos'!$C21:$F21)) -> 0
B22: VR Carrera 2 | C22: =+IF('Carga Tiempos'!C22=MIN('Carga Tiempos'!$C22:$F22),'Carga Tiempos'!C22,'Carga Tiempos'!C22-MIN('Carga Tiempos'!$C22:$F22)) -> 0 | D22: =+IF('Carga Tiempos'!D22=MIN('Carga Tiempos'!$C22:$F22),'Carga Tiempos'!D22,'Carga Tiempos'!D22-MIN('Carga Tiempos'!$C22:$F22)) -> 0 | E22: =+IF('Carga Tiempos'!E22=MIN('Carga Tiempos'!$C22:$F22),'Carga Tiempos'!E22,'Carga Tiempos'!E22-MIN('Carga Tiempos'!$C22:$F22)) -> 0 | F22: =+IF('Carga Tiempos'!F22=MIN('Carga Tiempos'!$C22:$F22),'Carga Tiempos'!F22,'Carga Tiempos'!F22-MIN('Carga Tiempos'!$C22:$F22)) -> 0 | G22: =+IF('Carga Tiempos'!G22=MIN('Carga Tiempos'!$C22:$F22),'Carga Tiempos'!G22,'Carga Tiempos'!G22-MIN('Carga Tiempos'!$C22:$F22)) -> 0 | H22: =+IF('Carga Tiempos'!H22=MIN('Carga Tiempos'!$C22:$F22),'Carga Tiempos'!H22,'Carga Tiempos'!H22-MIN('Carga Tiempos'!$C22:$F22)) -> 0 | I22: =+IF('Carga Tiempos'!I22=MIN('Carga Tiempos'!$C22:$F22),'Carga Tiempos'!I22,'Carga Tiempos'!I22-MIN('Carga Tiempos'!$C22:$F22)) -> 0 | J22: =+IF('Carga Tiempos'!J22=MIN('Carga Tiempos'!$C22:$F22),'Carga Tiempos'!J22,'Carga Tiempos'!J22-MIN('Carga Tiempos'!$C22:$F22)) -> 0 | ... M22: =+IF('Carga Tiempos'!M22=MIN('Carga Tiempos'!$C22:$F22),'Carga Tiempos'!M22,'Carga Tiempos'!M22-MIN('Carga Tiempos'!$C22:$F22)) -> 0
B23: Clasificacion | C23: =+IF('Carga Tiempos'!C23=MIN('Carga Tiempos'!$C23:$F23),'Carga Tiempos'!C23,'Carga Tiempos'!C23-MIN('Carga Tiempos'!$C23:$F23)) -> 0 | D23: =+IF('Carga Tiempos'!D23=MIN('Carga Tiempos'!$C23:$F23),'Carga Tiempos'!D23,'Carga Tiempos'!D23-MIN('Carga Tiempos'!$C23:$F23)) -> 0 | E23: =+IF('Carga Tiempos'!E23=MIN('Carga Tiempos'!$C23:$F23),'Carga Tiempos'!E23,'Carga Tiempos'!E23-MIN('Carga Tiempos'!$C23:$F23)) -> 0 | F23: =+IF('Carga Tiempos'!F23=MIN('Carga Tiempos'!$C23:$F23),'Carga Tiempos'!F23,'Carga Tiempos'!F23-MIN('Carga Tiempos'!$C23:$F23)) -> 0 | G23: =+IF('Carga Tiempos'!G23=MIN('Carga Tiempos'!$C23:$F23),'Carga Tiempos'!G23,'Carga Tiempos'!G23-MIN('Carga Tiempos'!$C23:$F23)) -> 0 | H23: =+IF('Carga Tiempos'!H23=MIN('Carga Tiempos'!$C23:$F23),'Carga Tiempos'!H23,'Carga Tiempos'!H23-MIN('Carga Tiempos'!$C23:$F23)) -> 0 | I23: =+IF('Carga Tiempos'!I23=MIN('Carga Tiempos'!$C23:$F23),'Carga Tiempos'!I23,'Carga Tiempos'!I23-MIN('Carga Tiempos'!$C23:$F23)) -> 0 | J23: =+IF('Carga Tiempos'!J23=MIN('Carga Tiempos'!$C23:$F23),'Carga Tiempos'!J23,'Carga Tiempos'!J23-MIN('Carga Tiempos'!$C23:$F23)) -> 0 | ... M23: =+IF('Carga Tiempos'!M23=MIN('Carga Tiempos'!$C23:$F23),'Carga Tiempos'!M23,'Carga Tiempos'!M23-MIN('Carga Tiempos'!$C23:$F23)) -> 0
B24: VR Carrera 1 | C24: =+IF('Carga Tiempos'!C24=MIN('Carga Tiempos'!$C24:$F24),'Carga Tiempos'!C24,'Carga Tiempos'!C24-MIN('Carga Tiempos'!$C24:$F24)) -> 0 | D24: =+IF('Carga Tiempos'!D24=MIN('Carga Tiempos'!$C24:$F24),'Carga Tiempos'!D24,'Carga Tiempos'!D24-MIN('Carga Tiempos'!$C24:$F24)) -> 0 | E24: =+IF('Carga Tiempos'!E24=MIN('Carga Tiempos'!$C24:$F24),'Carga Tiempos'!E24,'Carga Tiempos'!E24-MIN('Carga Tiempos'!$C24:$F24)) -> 0 | F24: =+IF('Carga Tiempos'!F24=MIN('Carga Tiempos'!$C24:$F24),'Carga Tiempos'!F24,'Carga Tiempos'!F24-MIN('Carga Tiempos'!$C24:$F24)) -> 0 | G24: =+IF('Carga Tiempos'!G24=MIN('Carga Tiempos'!$C24:$F24),'Carga Tiempos'!G24,'Carga Tiempos'!G24-MIN('Carga Tiempos'!$C24:$F24)) -> 0 | H24: =+IF('Carga Tiempos'!H24=MIN('Carga Tiempos'!$C24:$F24),'Carga Tiempos'!H24,'Carga Tiempos'!H24-MIN('Carga Tiempos'!$C24:$F24)) -> 0 | I24: =+IF('Carga Tiempos'!I24=MIN('Carga Tiempos'!$C24:$F24),'Carga Tiempos'!I24,'Carga Tiempos'!I24-MIN('Carga Tiempos'!$C24:$F24)) -> 0 | J24: =+IF('Carga Tiempos'!J24=MIN('Carga Tiempos'!$C24:$F24),'Carga Tiempos'!J24,'Carga Tiempos'!J24-MIN('Carga Tiempos'!$C24:$F24)) -> 0 | ... M24: =+IF('Carga Tiempos'!M24=MIN('Carga Tiempos'!$C24:$F24),'Carga Tiempos'!M24,'Carga Tiempos'!M24-MIN('Carga Tiempos'!$C24:$F24)) -> 0
B25: VR Carrera 2 | C25: =+IF('Carga Tiempos'!C25=MIN('Carga Tiempos'!$C25:$F25),'Carga Tiempos'!C25,'Carga Tiempos'!C25-MIN('Carga Tiempos'!$C25:$F25)) -> 0 | D25: =+IF('Carga Tiempos'!D25=MIN('Carga Tiempos'!$C25:$F25),'Carga Tiempos'!D25,'Carga Tiempos'!D25-MIN('Carga Tiempos'!$C25:$F25)) -> 0 | E25: =+IF('Carga Tiempos'!E25=MIN('Carga Tiempos'!$C25:$F25),'Carga Tiempos'!E25,'Carga Tiempos'!E25-MIN('Carga Tiempos'!$C25:$F25)) -> 0 | F25: =+IF('Carga Tiempos'!F25=MIN('Carga Tiempos'!$C25:$F25),'Carga Tiempos'!F25,'Carga Tiempos'!F25-MIN('Carga Tiempos'!$C25:$F25)) -> 0 | G25: =+IF('Carga Tiempos'!G25=MIN('Carga Tiempos'!$C25:$F25),'Carga Tiempos'!G25,'Carga Tiempos'!G25-MIN('Carga Tiempos'!$C25:$F25)) -> 0 | H25: =+IF('Carga Tiempos'!H25=MIN('Carga Tiempos'!$C25:$F25),'Carga Tiempos'!H25,'Carga Tiempos'!H25-MIN('Carga Tiempos'!$C25:$F25)) -> 0 | I25: =+IF('Carga Tiempos'!I25=MIN('Carga Tiempos'!$C25:$F25),'Carga Tiempos'!I25,'Carga Tiempos'!I25-MIN('Carga Tiempos'!$C25:$F25)) -> 0 | J25: =+IF('Carga Tiempos'!J25=MIN('Carga Tiempos'!$C25:$F25),'Carga Tiempos'!J25,'Carga Tiempos'!J25-MIN('Carga Tiempos'!$C25:$F25)) -> 0 | ... M25: =+IF('Carga Tiempos'!M25=MIN('Carga Tiempos'!$C25:$F25),'Carga Tiempos'!M25,'Carga Tiempos'!M25-MIN('Carga Tiempos'!$C25:$F25)) -> 0
... B31: VR Carrera 2 | C31: =+IF('Carga Tiempos'!C31=MIN('Carga Tiempos'!$C31:$F31),'Carga Tiempos'!C31,'Carga Tiempos'!C31-MIN('Carga Tiempos'!$C31:$F31)) -> 0 | D31: =+IF('Carga Tiempos'!D31=MIN('Carga Tiempos'!$C31:$F31),'Carga Tiempos'!D31,'Carga Tiempos'!D31-MIN('Carga Tiempos'!$C31:$F31)) -> 0 | E31: =+IF('Carga Tiempos'!E31=MIN('Carga Tiempos'!$C31:$F31),'Carga Tiempos'!E31,'Carga Tiempos'!E31-MIN('Carga Tiempos'!$C31:$F31)) -> 0 | F31: =+IF('Carga Tiempos'!F31=MIN('Carga Tiempos'!$C31:$F31),'Carga Tiempos'!F31,'Carga Tiempos'!F31-MIN('Carga Tiempos'!$C31:$F31)) -> 0 | G31: =+IF('Carga Tiempos'!G31=MIN('Carga Tiempos'!$C31:$F31),'Carga Tiempos'!G31,'Carga Tiempos'!G31-MIN('Carga Tiempos'!$C31:$F31)) -> 0 | H31: =+IF('Carga Tiempos'!H31=MIN('Carga Tiempos'!$C31:$F31),'Carga Tiempos'!H31,'Carga Tiempos'!H31-MIN('Carga Tiempos'!$C31:$F31)) -> 0 | I31: =+IF('Carga Tiempos'!I31=MIN('Carga Tiempos'!$C31:$F31),'Carga Tiempos'!I31,'Carga Tiempos'!I31-MIN('Carga Tiempos'!$C31:$F31)) -> 0 | J31: =+IF('Carga Tiempos'!J31=MIN('Carga Tiempos'!$C31:$F31),'Carga Tiempos'!J31,'Carga Tiempos'!J31-MIN('Carga Tiempos'!$C31:$F31)) -> 0 | ... M31: =+IF('Carga Tiempos'!M31=MIN('Carga Tiempos'!$C31:$F31),'Carga Tiempos'!M31,'Carga Tiempos'!M31-MIN('Carga Tiempos'!$C31:$F31)) -> 0

Sheet Diferencia en Carrera
A1: Carrera
A2: ROSARIO C1
A3: PILOTO | C3: PILOTO | E3: PILOTO | G3: PILOTO
A4: Agus C1 | C4: Ema C1 | E4: JuanF C1 | G4: Adri C1
A5: 1 | B5: 0.0011563889 | C5: 1 | D5: 0.0011333796 | E5: 1 | F5: 0.0011834375 | G5: 1 | H5: 0.0011095139
A6: 2 | B6: 0.0010512384 | C6: 2 | D6: 0.0010351736 | E6: 2 | F6: 0.0010527083 | G6: 2 | H6: 0.0010182292
A7: 3 | B7: 0.0010406597 | C7: 3 | D7: 0.0010439005 | E7: 3 | F7: 0.0010551968 | G7: 3 | H7: 0.0010220255
A8: 4 | B8: 0.0010437963 | C8: 4 | D8: 0.0010429282 | E8: 4 | F8: 0.0010487269 | G8: 4 | H8: 0.0010204282
A9: 5 | B9: 0.0010291782 | C9: 5 | D9: 0.0010516204 | E9: 5 | F9: 0.0010487153 | G9: 5 | H9: 0.0010226157
A10: 6 | B10: 0.0010416204 | C10: 6 | D10: 0.0010490972 | E10: 6 | F10: 0.0010729167 | G10: 6 | H10: 0.0010221991
A11: 7 | B11: 0.0010474306 | C11: 7 | D11: 0.0010388542 | E11: 7 | F11: 0.0010433796 | G11: 7 | H11: 0.0010287153
A12: 8 | B12: 0.0010408218 | C12: 8 | D12: 0.0010343634 | E12: 8 | F12: 0.0010781829 | G12: 8 | H12: 0.0010234375
A13: 9 | B13: 0.0010427431 | C13: 9 | D13: 0.0010282639 | E13: 9 | F13: 0.0010496644 | G13: 9 | H13: 0.0010294213
A14: 10 | B14: 0.0010472917 | C14: 10 | D14: 0.0010509375 | E14: 10 | F14: 0.0010534028 | G14: 10 | H14: 0.0010265278
A15: 11 | B15: 0.0010354051 | C15: 11 | D15: 0.0010414468 | E15: 11 | F15: 0.0010431134 | G15: 11 | H15: 0.0010215046
A16: 12 | B16: 0.0010411806 | C16: 12 | D16: 0.0010483681 | E16: 12 | F16: 0.0010588889 | G16: 12 | H16: 0.0010217245
... A19: 15 | B19: 0.0010400231 | C19: 15 | D19: 0.001041875 | E19: 15 | F19: 0.0010623148 | G19: 15 | H19: 0.0010273495
A20: 16 | B20: 0.0010518056 | C20: 16 | D20: 0.0010398958 | E20: 16 | F20: 0.0010468519 | G20: 16 | H20: 0.001027581 | L20: =+AVERAGE(L3:L10,L14:L17) -> #DIV/0! | N20: =+AVERAGE(N3:N10,N14:N17) -> #DIV/0! | P20: =+AVERAGE(P3:P10,P14:P17) -> #DIV/0! | R20: =+AVERAGE(R3:R10,R14:R17) -> #DIV/0!
A21: 17 | B21: 0.0010396875 | C21: 17 | D21: 0.0010369213 | E21: 17 | F21: 0.0010374074 | G21: 17 | H21: 0.0010328241
A22: 18 | B22: 0.0010963542 | C22: 18 | D22: 0.0010872569 | E22: 18 | F22: 0.0011273611 | G22: 18 | H22: 0.0010513657 | L22: =+AVERAGE(L20:L21) -> #DIV/0! | N22: =+SUM(N20-L20) -> #DIV/0! | P22: =+SUM(P20-L20) -> #DIV/0! | R22: =+SUM(R20-L20) -> #DIV/0!
A23: 19 | B23: 0.0014269213 | C23: 19 | D23: 0.0014564468 | E23: 19 | F23: 0.0011922338 | G23: 19 | H23: 0.0017965278
